[2024-06-25 12:35:36,143][flwr][INFO] - Starting Flower simulation, config: ServerConfig(num_rounds=10000, round_timeout=None)
[2024-06-25 12:35:38,515][flwr][INFO] - Flower VCE: Ray initialized with resources: {'CPU': 8.0, 'object_store_memory': 1318148505.0, 'node:__internal_head__': 1.0, 'node:127.0.0.1': 1.0, 'memory': 2636297012.0}
[2024-06-25 12:35:38,515][flwr][INFO] - Optimize your simulation with Flower VCE: https://flower.dev/docs/framework/how-to-run-simulations.html
[2024-06-25 12:35:38,515][flwr][INFO] - Flower VCE: Resources for each Virtual Client: {'num_cpus': 1.0, 'num_gpus': 0}
[2024-06-25 12:35:38,524][flwr][INFO] - Flower VCE: Creating VirtualClientEngineActorPool with 8 actors
[2024-06-25 12:35:38,524][flwr][INFO] - Initializing global parameters
[2024-06-25 12:35:38,524][flwr][INFO] - Using initial parameters provided by strategy
[2024-06-25 12:35:38,524][flwr][INFO] - Evaluating initial parameters
[2024-06-25 12:35:51,193][flwr][INFO] - initial parameters (loss, other metrics): 0.2418656432390213, {'accuracy': 0.1085}
[2024-06-25 12:35:51,193][flwr][INFO] - FL starting
[2024-06-25 12:35:51,243][flwr][DEBUG] - fit_round 1: strategy sampled 35 clients (out of 100)
[2024-06-25 12:36:41,898][flwr][ERROR] - Traceback (most recent call last):
  File "/Users/saisatyajonnalagadda/miniforge3/envs/carbFL/lib/python3.10/site-packages/flwr/simulation/ray_transport/ray_client_proxy.py", line 138, in _submit_job
    res = self.actor_pool.get_client_result(self.cid, timeout)
  File "/Users/saisatyajonnalagadda/miniforge3/envs/carbFL/lib/python3.10/site-packages/flwr/simulation/ray_transport/ray_actor.py", line 414, in get_client_result
    return self._fetch_future_result(cid)
  File "/Users/saisatyajonnalagadda/miniforge3/envs/carbFL/lib/python3.10/site-packages/flwr/simulation/ray_transport/ray_actor.py", line 300, in _fetch_future_result
    res_cid, res = ray.get(future)  # type: (str, ClientRes)
  File "/Users/saisatyajonnalagadda/miniforge3/envs/carbFL/lib/python3.10/site-packages/ray/_private/auto_init_hook.py", line 24, in auto_init_wrapper
    return fn(*args, **kwargs)
  File "/Users/saisatyajonnalagadda/miniforge3/envs/carbFL/lib/python3.10/site-packages/ray/_private/client_mode_hook.py", line 103, in wrapper
    return func(*args, **kwargs)
  File "/Users/saisatyajonnalagadda/miniforge3/envs/carbFL/lib/python3.10/site-packages/ray/_private/worker.py", line 2524, in get
    raise value.as_instanceof_cause()
ray.exceptions.RayTaskError(ClientException): [36mray::DefaultActor.run()[39m (pid=92180, ip=127.0.0.1, actor_id=f8c11dae005792bd612a039001000000, repr=<flwr.simulation.ray_transport.ray_actor.DefaultActor object at 0x109bfe080>)
  File "/Users/saisatyajonnalagadda/current_projects/carb_aware_model_adaption_FL/main2.py", line 116, in client_fn
    trainloader=trainloaders[client_id],
IndexError: list index out of range

The above exception was the direct cause of the following exception:

[36mray::DefaultActor.run()[39m (pid=92180, ip=127.0.0.1, actor_id=f8c11dae005792bd612a039001000000, repr=<flwr.simulation.ray_transport.ray_actor.DefaultActor object at 0x109bfe080>)
  File "/Users/saisatyajonnalagadda/miniforge3/envs/carbFL/lib/python3.10/site-packages/flwr/simulation/ray_transport/ray_actor.py", line 84, in run
    raise ClientException(str(message)) from ex
flwr.simulation.ray_transport.ray_actor.ClientException: 
>>>>>>>A ClientException occurred.('\n\tSomething went wrong when running your client workload.\n\tClient 53_Sydney_large crashed when the DefaultActor was running its workload.\n\tException triggered on the client side: Traceback (most recent call last):\n  File "/Users/saisatyajonnalagadda/miniforge3/envs/carbFL/lib/python3.10/site-packages/flwr/simulation/ray_transport/ray_actor.py", line 70, in run\n    client = check_clientfn_returns_client(client_fn(cid))\n  File "/Users/saisatyajonnalagadda/current_projects/carb_aware_model_adaption_FL/main2.py", line 116, in client_fn\n    trainloader=trainloaders[client_id],\nIndexError: list index out of range\n',)

[2024-06-25 12:36:41,949][flwr][ERROR] - [36mray::DefaultActor.run()[39m (pid=92180, ip=127.0.0.1, actor_id=f8c11dae005792bd612a039001000000, repr=<flwr.simulation.ray_transport.ray_actor.DefaultActor object at 0x109bfe080>)
  File "/Users/saisatyajonnalagadda/current_projects/carb_aware_model_adaption_FL/main2.py", line 116, in client_fn
    trainloader=trainloaders[client_id],
IndexError: list index out of range

The above exception was the direct cause of the following exception:

[36mray::DefaultActor.run()[39m (pid=92180, ip=127.0.0.1, actor_id=f8c11dae005792bd612a039001000000, repr=<flwr.simulation.ray_transport.ray_actor.DefaultActor object at 0x109bfe080>)
  File "/Users/saisatyajonnalagadda/miniforge3/envs/carbFL/lib/python3.10/site-packages/flwr/simulation/ray_transport/ray_actor.py", line 84, in run
    raise ClientException(str(message)) from ex
flwr.simulation.ray_transport.ray_actor.ClientException: 
>>>>>>>A ClientException occurred.('\n\tSomething went wrong when running your client workload.\n\tClient 53_Sydney_large crashed when the DefaultActor was running its workload.\n\tException triggered on the client side: Traceback (most recent call last):\n  File "/Users/saisatyajonnalagadda/miniforge3/envs/carbFL/lib/python3.10/site-packages/flwr/simulation/ray_transport/ray_actor.py", line 70, in run\n    client = check_clientfn_returns_client(client_fn(cid))\n  File "/Users/saisatyajonnalagadda/current_projects/carb_aware_model_adaption_FL/main2.py", line 116, in client_fn\n    trainloader=trainloaders[client_id],\nIndexError: list index out of range\n',)
[2024-06-25 12:36:49,711][flwr][ERROR] - Traceback (most recent call last):
  File "/Users/saisatyajonnalagadda/miniforge3/envs/carbFL/lib/python3.10/site-packages/flwr/simulation/ray_transport/ray_client_proxy.py", line 138, in _submit_job
    res = self.actor_pool.get_client_result(self.cid, timeout)
  File "/Users/saisatyajonnalagadda/miniforge3/envs/carbFL/lib/python3.10/site-packages/flwr/simulation/ray_transport/ray_actor.py", line 414, in get_client_result
    return self._fetch_future_result(cid)
  File "/Users/saisatyajonnalagadda/miniforge3/envs/carbFL/lib/python3.10/site-packages/flwr/simulation/ray_transport/ray_actor.py", line 300, in _fetch_future_result
    res_cid, res = ray.get(future)  # type: (str, ClientRes)
  File "/Users/saisatyajonnalagadda/miniforge3/envs/carbFL/lib/python3.10/site-packages/ray/_private/auto_init_hook.py", line 24, in auto_init_wrapper
    return fn(*args, **kwargs)
  File "/Users/saisatyajonnalagadda/miniforge3/envs/carbFL/lib/python3.10/site-packages/ray/_private/client_mode_hook.py", line 103, in wrapper
    return func(*args, **kwargs)
  File "/Users/saisatyajonnalagadda/miniforge3/envs/carbFL/lib/python3.10/site-packages/ray/_private/worker.py", line 2524, in get
    raise value.as_instanceof_cause()
ray.exceptions.RayTaskError(ClientException): [36mray::DefaultActor.run()[39m (pid=92180, ip=127.0.0.1, actor_id=f8c11dae005792bd612a039001000000, repr=<flwr.simulation.ray_transport.ray_actor.DefaultActor object at 0x109bfe080>)
  File "/Users/saisatyajonnalagadda/current_projects/carb_aware_model_adaption_FL/main2.py", line 116, in client_fn
    trainloader=trainloaders[client_id],
IndexError: list index out of range

The above exception was the direct cause of the following exception:

[36mray::DefaultActor.run()[39m (pid=92180, ip=127.0.0.1, actor_id=f8c11dae005792bd612a039001000000, repr=<flwr.simulation.ray_transport.ray_actor.DefaultActor object at 0x109bfe080>)
  File "/Users/saisatyajonnalagadda/miniforge3/envs/carbFL/lib/python3.10/site-packages/flwr/simulation/ray_transport/ray_actor.py", line 84, in run
    raise ClientException(str(message)) from ex
flwr.simulation.ray_transport.ray_actor.ClientException: 
>>>>>>>A ClientException occurred.('\n\tSomething went wrong when running your client workload.\n\tClient 74_Hong Kong_large crashed when the DefaultActor was running its workload.\n\tException triggered on the client side: Traceback (most recent call last):\n  File "/Users/saisatyajonnalagadda/miniforge3/envs/carbFL/lib/python3.10/site-packages/flwr/simulation/ray_transport/ray_actor.py", line 70, in run\n    client = check_clientfn_returns_client(client_fn(cid))\n  File "/Users/saisatyajonnalagadda/current_projects/carb_aware_model_adaption_FL/main2.py", line 116, in client_fn\n    trainloader=trainloaders[client_id],\nIndexError: list index out of range\n',)

[2024-06-25 12:36:49,719][flwr][ERROR] - [36mray::DefaultActor.run()[39m (pid=92180, ip=127.0.0.1, actor_id=f8c11dae005792bd612a039001000000, repr=<flwr.simulation.ray_transport.ray_actor.DefaultActor object at 0x109bfe080>)
  File "/Users/saisatyajonnalagadda/current_projects/carb_aware_model_adaption_FL/main2.py", line 116, in client_fn
    trainloader=trainloaders[client_id],
IndexError: list index out of range

The above exception was the direct cause of the following exception:

[36mray::DefaultActor.run()[39m (pid=92180, ip=127.0.0.1, actor_id=f8c11dae005792bd612a039001000000, repr=<flwr.simulation.ray_transport.ray_actor.DefaultActor object at 0x109bfe080>)
  File "/Users/saisatyajonnalagadda/miniforge3/envs/carbFL/lib/python3.10/site-packages/flwr/simulation/ray_transport/ray_actor.py", line 84, in run
    raise ClientException(str(message)) from ex
flwr.simulation.ray_transport.ray_actor.ClientException: 
>>>>>>>A ClientException occurred.('\n\tSomething went wrong when running your client workload.\n\tClient 74_Hong Kong_large crashed when the DefaultActor was running its workload.\n\tException triggered on the client side: Traceback (most recent call last):\n  File "/Users/saisatyajonnalagadda/miniforge3/envs/carbFL/lib/python3.10/site-packages/flwr/simulation/ray_transport/ray_actor.py", line 70, in run\n    client = check_clientfn_returns_client(client_fn(cid))\n  File "/Users/saisatyajonnalagadda/current_projects/carb_aware_model_adaption_FL/main2.py", line 116, in client_fn\n    trainloader=trainloaders[client_id],\nIndexError: list index out of range\n',)
[2024-06-25 12:36:49,734][flwr][ERROR] - Traceback (most recent call last):
  File "/Users/saisatyajonnalagadda/miniforge3/envs/carbFL/lib/python3.10/site-packages/flwr/simulation/ray_transport/ray_client_proxy.py", line 138, in _submit_job
    res = self.actor_pool.get_client_result(self.cid, timeout)
  File "/Users/saisatyajonnalagadda/miniforge3/envs/carbFL/lib/python3.10/site-packages/flwr/simulation/ray_transport/ray_actor.py", line 414, in get_client_result
    return self._fetch_future_result(cid)
  File "/Users/saisatyajonnalagadda/miniforge3/envs/carbFL/lib/python3.10/site-packages/flwr/simulation/ray_transport/ray_actor.py", line 300, in _fetch_future_result
    res_cid, res = ray.get(future)  # type: (str, ClientRes)
  File "/Users/saisatyajonnalagadda/miniforge3/envs/carbFL/lib/python3.10/site-packages/ray/_private/auto_init_hook.py", line 24, in auto_init_wrapper
    return fn(*args, **kwargs)
  File "/Users/saisatyajonnalagadda/miniforge3/envs/carbFL/lib/python3.10/site-packages/ray/_private/client_mode_hook.py", line 103, in wrapper
    return func(*args, **kwargs)
  File "/Users/saisatyajonnalagadda/miniforge3/envs/carbFL/lib/python3.10/site-packages/ray/_private/worker.py", line 2524, in get
    raise value.as_instanceof_cause()
ray.exceptions.RayTaskError(ClientException): [36mray::DefaultActor.run()[39m (pid=92187, ip=127.0.0.1, actor_id=99ee256a1db7a48f08793abb01000000, repr=<flwr.simulation.ray_transport.ray_actor.DefaultActor object at 0x13049a050>)
  File "/Users/saisatyajonnalagadda/current_projects/carb_aware_model_adaption_FL/main2.py", line 116, in client_fn
    trainloader=trainloaders[client_id],
IndexError: list index out of range

The above exception was the direct cause of the following exception:

[36mray::DefaultActor.run()[39m (pid=92187, ip=127.0.0.1, actor_id=99ee256a1db7a48f08793abb01000000, repr=<flwr.simulation.ray_transport.ray_actor.DefaultActor object at 0x13049a050>)
  File "/Users/saisatyajonnalagadda/miniforge3/envs/carbFL/lib/python3.10/site-packages/flwr/simulation/ray_transport/ray_actor.py", line 84, in run
    raise ClientException(str(message)) from ex
flwr.simulation.ray_transport.ray_actor.ClientException: 
>>>>>>>A ClientException occurred.('\n\tSomething went wrong when running your client workload.\n\tClient 76_Sydney_large crashed when the DefaultActor was running its workload.\n\tException triggered on the client side: Traceback (most recent call last):\n  File "/Users/saisatyajonnalagadda/miniforge3/envs/carbFL/lib/python3.10/site-packages/flwr/simulation/ray_transport/ray_actor.py", line 70, in run\n    client = check_clientfn_returns_client(client_fn(cid))\n  File "/Users/saisatyajonnalagadda/current_projects/carb_aware_model_adaption_FL/main2.py", line 116, in client_fn\n    trainloader=trainloaders[client_id],\nIndexError: list index out of range\n',)

[2024-06-25 12:36:49,755][flwr][ERROR] - Traceback (most recent call last):
  File "/Users/saisatyajonnalagadda/miniforge3/envs/carbFL/lib/python3.10/site-packages/flwr/simulation/ray_transport/ray_client_proxy.py", line 138, in _submit_job
    res = self.actor_pool.get_client_result(self.cid, timeout)
  File "/Users/saisatyajonnalagadda/miniforge3/envs/carbFL/lib/python3.10/site-packages/flwr/simulation/ray_transport/ray_actor.py", line 414, in get_client_result
    return self._fetch_future_result(cid)
  File "/Users/saisatyajonnalagadda/miniforge3/envs/carbFL/lib/python3.10/site-packages/flwr/simulation/ray_transport/ray_actor.py", line 300, in _fetch_future_result
    res_cid, res = ray.get(future)  # type: (str, ClientRes)
  File "/Users/saisatyajonnalagadda/miniforge3/envs/carbFL/lib/python3.10/site-packages/ray/_private/auto_init_hook.py", line 24, in auto_init_wrapper
    return fn(*args, **kwargs)
  File "/Users/saisatyajonnalagadda/miniforge3/envs/carbFL/lib/python3.10/site-packages/ray/_private/client_mode_hook.py", line 103, in wrapper
    return func(*args, **kwargs)
  File "/Users/saisatyajonnalagadda/miniforge3/envs/carbFL/lib/python3.10/site-packages/ray/_private/worker.py", line 2524, in get
    raise value.as_instanceof_cause()
ray.exceptions.RayTaskError(ClientException): [36mray::DefaultActor.run()[39m (pid=92180, ip=127.0.0.1, actor_id=f8c11dae005792bd612a039001000000, repr=<flwr.simulation.ray_transport.ray_actor.DefaultActor object at 0x109bfe080>)
  File "/Users/saisatyajonnalagadda/current_projects/carb_aware_model_adaption_FL/main2.py", line 116, in client_fn
    trainloader=trainloaders[client_id],
IndexError: list index out of range

The above exception was the direct cause of the following exception:

[36mray::DefaultActor.run()[39m (pid=92180, ip=127.0.0.1, actor_id=f8c11dae005792bd612a039001000000, repr=<flwr.simulation.ray_transport.ray_actor.DefaultActor object at 0x109bfe080>)
  File "/Users/saisatyajonnalagadda/miniforge3/envs/carbFL/lib/python3.10/site-packages/flwr/simulation/ray_transport/ray_actor.py", line 84, in run
    raise ClientException(str(message)) from ex
flwr.simulation.ray_transport.ray_actor.ClientException: 
>>>>>>>A ClientException occurred.('\n\tSomething went wrong when running your client workload.\n\tClient 81_Sydney_large crashed when the DefaultActor was running its workload.\n\tException triggered on the client side: Traceback (most recent call last):\n  File "/Users/saisatyajonnalagadda/miniforge3/envs/carbFL/lib/python3.10/site-packages/flwr/simulation/ray_transport/ray_actor.py", line 70, in run\n    client = check_clientfn_returns_client(client_fn(cid))\n  File "/Users/saisatyajonnalagadda/current_projects/carb_aware_model_adaption_FL/main2.py", line 116, in client_fn\n    trainloader=trainloaders[client_id],\nIndexError: list index out of range\n',)

[2024-06-25 12:36:49,788][flwr][ERROR] - [36mray::DefaultActor.run()[39m (pid=92187, ip=127.0.0.1, actor_id=99ee256a1db7a48f08793abb01000000, repr=<flwr.simulation.ray_transport.ray_actor.DefaultActor object at 0x13049a050>)
  File "/Users/saisatyajonnalagadda/current_projects/carb_aware_model_adaption_FL/main2.py", line 116, in client_fn
    trainloader=trainloaders[client_id],
IndexError: list index out of range

The above exception was the direct cause of the following exception:

[36mray::DefaultActor.run()[39m (pid=92187, ip=127.0.0.1, actor_id=99ee256a1db7a48f08793abb01000000, repr=<flwr.simulation.ray_transport.ray_actor.DefaultActor object at 0x13049a050>)
  File "/Users/saisatyajonnalagadda/miniforge3/envs/carbFL/lib/python3.10/site-packages/flwr/simulation/ray_transport/ray_actor.py", line 84, in run
    raise ClientException(str(message)) from ex
flwr.simulation.ray_transport.ray_actor.ClientException: 
>>>>>>>A ClientException occurred.('\n\tSomething went wrong when running your client workload.\n\tClient 76_Sydney_large crashed when the DefaultActor was running its workload.\n\tException triggered on the client side: Traceback (most recent call last):\n  File "/Users/saisatyajonnalagadda/miniforge3/envs/carbFL/lib/python3.10/site-packages/flwr/simulation/ray_transport/ray_actor.py", line 70, in run\n    client = check_clientfn_returns_client(client_fn(cid))\n  File "/Users/saisatyajonnalagadda/current_projects/carb_aware_model_adaption_FL/main2.py", line 116, in client_fn\n    trainloader=trainloaders[client_id],\nIndexError: list index out of range\n',)
[2024-06-25 12:36:49,813][flwr][ERROR] - [36mray::DefaultActor.run()[39m (pid=92180, ip=127.0.0.1, actor_id=f8c11dae005792bd612a039001000000, repr=<flwr.simulation.ray_transport.ray_actor.DefaultActor object at 0x109bfe080>)
  File "/Users/saisatyajonnalagadda/current_projects/carb_aware_model_adaption_FL/main2.py", line 116, in client_fn
    trainloader=trainloaders[client_id],
IndexError: list index out of range

The above exception was the direct cause of the following exception:

[36mray::DefaultActor.run()[39m (pid=92180, ip=127.0.0.1, actor_id=f8c11dae005792bd612a039001000000, repr=<flwr.simulation.ray_transport.ray_actor.DefaultActor object at 0x109bfe080>)
  File "/Users/saisatyajonnalagadda/miniforge3/envs/carbFL/lib/python3.10/site-packages/flwr/simulation/ray_transport/ray_actor.py", line 84, in run
    raise ClientException(str(message)) from ex
flwr.simulation.ray_transport.ray_actor.ClientException: 
>>>>>>>A ClientException occurred.('\n\tSomething went wrong when running your client workload.\n\tClient 81_Sydney_large crashed when the DefaultActor was running its workload.\n\tException triggered on the client side: Traceback (most recent call last):\n  File "/Users/saisatyajonnalagadda/miniforge3/envs/carbFL/lib/python3.10/site-packages/flwr/simulation/ray_transport/ray_actor.py", line 70, in run\n    client = check_clientfn_returns_client(client_fn(cid))\n  File "/Users/saisatyajonnalagadda/current_projects/carb_aware_model_adaption_FL/main2.py", line 116, in client_fn\n    trainloader=trainloaders[client_id],\nIndexError: list index out of range\n',)
[2024-06-25 12:36:52,787][flwr][ERROR] - Traceback (most recent call last):
  File "/Users/saisatyajonnalagadda/miniforge3/envs/carbFL/lib/python3.10/site-packages/flwr/simulation/ray_transport/ray_client_proxy.py", line 138, in _submit_job
    res = self.actor_pool.get_client_result(self.cid, timeout)
  File "/Users/saisatyajonnalagadda/miniforge3/envs/carbFL/lib/python3.10/site-packages/flwr/simulation/ray_transport/ray_actor.py", line 414, in get_client_result
    return self._fetch_future_result(cid)
  File "/Users/saisatyajonnalagadda/miniforge3/envs/carbFL/lib/python3.10/site-packages/flwr/simulation/ray_transport/ray_actor.py", line 300, in _fetch_future_result
    res_cid, res = ray.get(future)  # type: (str, ClientRes)
  File "/Users/saisatyajonnalagadda/miniforge3/envs/carbFL/lib/python3.10/site-packages/ray/_private/auto_init_hook.py", line 24, in auto_init_wrapper
    return fn(*args, **kwargs)
  File "/Users/saisatyajonnalagadda/miniforge3/envs/carbFL/lib/python3.10/site-packages/ray/_private/client_mode_hook.py", line 103, in wrapper
    return func(*args, **kwargs)
  File "/Users/saisatyajonnalagadda/miniforge3/envs/carbFL/lib/python3.10/site-packages/ray/_private/worker.py", line 2524, in get
    raise value.as_instanceof_cause()
ray.exceptions.RayTaskError(ClientException): [36mray::DefaultActor.run()[39m (pid=92187, ip=127.0.0.1, actor_id=99ee256a1db7a48f08793abb01000000, repr=<flwr.simulation.ray_transport.ray_actor.DefaultActor object at 0x13049a050>)
  File "/Users/saisatyajonnalagadda/current_projects/carb_aware_model_adaption_FL/main2.py", line 116, in client_fn
    trainloader=trainloaders[client_id],
IndexError: list index out of range

The above exception was the direct cause of the following exception:

[36mray::DefaultActor.run()[39m (pid=92187, ip=127.0.0.1, actor_id=99ee256a1db7a48f08793abb01000000, repr=<flwr.simulation.ray_transport.ray_actor.DefaultActor object at 0x13049a050>)
  File "/Users/saisatyajonnalagadda/miniforge3/envs/carbFL/lib/python3.10/site-packages/flwr/simulation/ray_transport/ray_actor.py", line 84, in run
    raise ClientException(str(message)) from ex
flwr.simulation.ray_transport.ray_actor.ClientException: 
>>>>>>>A ClientException occurred.('\n\tSomething went wrong when running your client workload.\n\tClient 55_Hong Kong_large crashed when the DefaultActor was running its workload.\n\tException triggered on the client side: Traceback (most recent call last):\n  File "/Users/saisatyajonnalagadda/miniforge3/envs/carbFL/lib/python3.10/site-packages/flwr/simulation/ray_transport/ray_actor.py", line 70, in run\n    client = check_clientfn_returns_client(client_fn(cid))\n  File "/Users/saisatyajonnalagadda/current_projects/carb_aware_model_adaption_FL/main2.py", line 116, in client_fn\n    trainloader=trainloaders[client_id],\nIndexError: list index out of range\n',)

[2024-06-25 12:36:52,827][flwr][ERROR] - [36mray::DefaultActor.run()[39m (pid=92187, ip=127.0.0.1, actor_id=99ee256a1db7a48f08793abb01000000, repr=<flwr.simulation.ray_transport.ray_actor.DefaultActor object at 0x13049a050>)
  File "/Users/saisatyajonnalagadda/current_projects/carb_aware_model_adaption_FL/main2.py", line 116, in client_fn
    trainloader=trainloaders[client_id],
IndexError: list index out of range

The above exception was the direct cause of the following exception:

[36mray::DefaultActor.run()[39m (pid=92187, ip=127.0.0.1, actor_id=99ee256a1db7a48f08793abb01000000, repr=<flwr.simulation.ray_transport.ray_actor.DefaultActor object at 0x13049a050>)
  File "/Users/saisatyajonnalagadda/miniforge3/envs/carbFL/lib/python3.10/site-packages/flwr/simulation/ray_transport/ray_actor.py", line 84, in run
    raise ClientException(str(message)) from ex
flwr.simulation.ray_transport.ray_actor.ClientException: 
>>>>>>>A ClientException occurred.('\n\tSomething went wrong when running your client workload.\n\tClient 55_Hong Kong_large crashed when the DefaultActor was running its workload.\n\tException triggered on the client side: Traceback (most recent call last):\n  File "/Users/saisatyajonnalagadda/miniforge3/envs/carbFL/lib/python3.10/site-packages/flwr/simulation/ray_transport/ray_actor.py", line 70, in run\n    client = check_clientfn_returns_client(client_fn(cid))\n  File "/Users/saisatyajonnalagadda/current_projects/carb_aware_model_adaption_FL/main2.py", line 116, in client_fn\n    trainloader=trainloaders[client_id],\nIndexError: list index out of range\n',)
[2024-06-25 12:37:06,984][flwr][ERROR] - Traceback (most recent call last):
  File "/Users/saisatyajonnalagadda/miniforge3/envs/carbFL/lib/python3.10/site-packages/flwr/simulation/ray_transport/ray_client_proxy.py", line 138, in _submit_job
    res = self.actor_pool.get_client_result(self.cid, timeout)
  File "/Users/saisatyajonnalagadda/miniforge3/envs/carbFL/lib/python3.10/site-packages/flwr/simulation/ray_transport/ray_actor.py", line 414, in get_client_result
    return self._fetch_future_result(cid)
  File "/Users/saisatyajonnalagadda/miniforge3/envs/carbFL/lib/python3.10/site-packages/flwr/simulation/ray_transport/ray_actor.py", line 300, in _fetch_future_result
    res_cid, res = ray.get(future)  # type: (str, ClientRes)
  File "/Users/saisatyajonnalagadda/miniforge3/envs/carbFL/lib/python3.10/site-packages/ray/_private/auto_init_hook.py", line 24, in auto_init_wrapper
    return fn(*args, **kwargs)
  File "/Users/saisatyajonnalagadda/miniforge3/envs/carbFL/lib/python3.10/site-packages/ray/_private/client_mode_hook.py", line 103, in wrapper
    return func(*args, **kwargs)
  File "/Users/saisatyajonnalagadda/miniforge3/envs/carbFL/lib/python3.10/site-packages/ray/_private/worker.py", line 2524, in get
    raise value.as_instanceof_cause()
ray.exceptions.RayTaskError(ClientException): [36mray::DefaultActor.run()[39m (pid=92180, ip=127.0.0.1, actor_id=f8c11dae005792bd612a039001000000, repr=<flwr.simulation.ray_transport.ray_actor.DefaultActor object at 0x109bfe080>)
  File "/Users/saisatyajonnalagadda/current_projects/carb_aware_model_adaption_FL/main2.py", line 116, in client_fn
    trainloader=trainloaders[client_id],
IndexError: list index out of range

The above exception was the direct cause of the following exception:

[36mray::DefaultActor.run()[39m (pid=92180, ip=127.0.0.1, actor_id=f8c11dae005792bd612a039001000000, repr=<flwr.simulation.ray_transport.ray_actor.DefaultActor object at 0x109bfe080>)
  File "/Users/saisatyajonnalagadda/miniforge3/envs/carbFL/lib/python3.10/site-packages/flwr/simulation/ray_transport/ray_actor.py", line 84, in run
    raise ClientException(str(message)) from ex
flwr.simulation.ray_transport.ray_actor.ClientException: 
>>>>>>>A ClientException occurred.('\n\tSomething went wrong when running your client workload.\n\tClient 96_San Francisco_large crashed when the DefaultActor was running its workload.\n\tException triggered on the client side: Traceback (most recent call last):\n  File "/Users/saisatyajonnalagadda/miniforge3/envs/carbFL/lib/python3.10/site-packages/flwr/simulation/ray_transport/ray_actor.py", line 70, in run\n    client = check_clientfn_returns_client(client_fn(cid))\n  File "/Users/saisatyajonnalagadda/current_projects/carb_aware_model_adaption_FL/main2.py", line 116, in client_fn\n    trainloader=trainloaders[client_id],\nIndexError: list index out of range\n',)

[2024-06-25 12:37:07,427][flwr][ERROR] - [36mray::DefaultActor.run()[39m (pid=92180, ip=127.0.0.1, actor_id=f8c11dae005792bd612a039001000000, repr=<flwr.simulation.ray_transport.ray_actor.DefaultActor object at 0x109bfe080>)
  File "/Users/saisatyajonnalagadda/current_projects/carb_aware_model_adaption_FL/main2.py", line 116, in client_fn
    trainloader=trainloaders[client_id],
IndexError: list index out of range

The above exception was the direct cause of the following exception:

[36mray::DefaultActor.run()[39m (pid=92180, ip=127.0.0.1, actor_id=f8c11dae005792bd612a039001000000, repr=<flwr.simulation.ray_transport.ray_actor.DefaultActor object at 0x109bfe080>)
  File "/Users/saisatyajonnalagadda/miniforge3/envs/carbFL/lib/python3.10/site-packages/flwr/simulation/ray_transport/ray_actor.py", line 84, in run
    raise ClientException(str(message)) from ex
flwr.simulation.ray_transport.ray_actor.ClientException: 
>>>>>>>A ClientException occurred.('\n\tSomething went wrong when running your client workload.\n\tClient 96_San Francisco_large crashed when the DefaultActor was running its workload.\n\tException triggered on the client side: Traceback (most recent call last):\n  File "/Users/saisatyajonnalagadda/miniforge3/envs/carbFL/lib/python3.10/site-packages/flwr/simulation/ray_transport/ray_actor.py", line 70, in run\n    client = check_clientfn_returns_client(client_fn(cid))\n  File "/Users/saisatyajonnalagadda/current_projects/carb_aware_model_adaption_FL/main2.py", line 116, in client_fn\n    trainloader=trainloaders[client_id],\nIndexError: list index out of range\n',)
[2024-06-25 12:37:13,821][flwr][ERROR] - Traceback (most recent call last):
  File "/Users/saisatyajonnalagadda/miniforge3/envs/carbFL/lib/python3.10/site-packages/flwr/simulation/ray_transport/ray_client_proxy.py", line 138, in _submit_job
    res = self.actor_pool.get_client_result(self.cid, timeout)
  File "/Users/saisatyajonnalagadda/miniforge3/envs/carbFL/lib/python3.10/site-packages/flwr/simulation/ray_transport/ray_actor.py", line 414, in get_client_result
    return self._fetch_future_result(cid)
  File "/Users/saisatyajonnalagadda/miniforge3/envs/carbFL/lib/python3.10/site-packages/flwr/simulation/ray_transport/ray_actor.py", line 300, in _fetch_future_result
    res_cid, res = ray.get(future)  # type: (str, ClientRes)
  File "/Users/saisatyajonnalagadda/miniforge3/envs/carbFL/lib/python3.10/site-packages/ray/_private/auto_init_hook.py", line 24, in auto_init_wrapper
    return fn(*args, **kwargs)
  File "/Users/saisatyajonnalagadda/miniforge3/envs/carbFL/lib/python3.10/site-packages/ray/_private/client_mode_hook.py", line 103, in wrapper
    return func(*args, **kwargs)
  File "/Users/saisatyajonnalagadda/miniforge3/envs/carbFL/lib/python3.10/site-packages/ray/_private/worker.py", line 2524, in get
    raise value.as_instanceof_cause()
ray.exceptions.RayTaskError(ClientException): [36mray::DefaultActor.run()[39m (pid=92187, ip=127.0.0.1, actor_id=99ee256a1db7a48f08793abb01000000, repr=<flwr.simulation.ray_transport.ray_actor.DefaultActor object at 0x13049a050>)
  File "/Users/saisatyajonnalagadda/current_projects/carb_aware_model_adaption_FL/main2.py", line 116, in client_fn
    trainloader=trainloaders[client_id],
IndexError: list index out of range

The above exception was the direct cause of the following exception:

[36mray::DefaultActor.run()[39m (pid=92187, ip=127.0.0.1, actor_id=99ee256a1db7a48f08793abb01000000, repr=<flwr.simulation.ray_transport.ray_actor.DefaultActor object at 0x13049a050>)
  File "/Users/saisatyajonnalagadda/miniforge3/envs/carbFL/lib/python3.10/site-packages/flwr/simulation/ray_transport/ray_actor.py", line 84, in run
    raise ClientException(str(message)) from ex
flwr.simulation.ray_transport.ray_actor.ClientException: 
>>>>>>>A ClientException occurred.('\n\tSomething went wrong when running your client workload.\n\tClient 91_San Francisco_large crashed when the DefaultActor was running its workload.\n\tException triggered on the client side: Traceback (most recent call last):\n  File "/Users/saisatyajonnalagadda/miniforge3/envs/carbFL/lib/python3.10/site-packages/flwr/simulation/ray_transport/ray_actor.py", line 70, in run\n    client = check_clientfn_returns_client(client_fn(cid))\n  File "/Users/saisatyajonnalagadda/current_projects/carb_aware_model_adaption_FL/main2.py", line 116, in client_fn\n    trainloader=trainloaders[client_id],\nIndexError: list index out of range\n',)

[2024-06-25 12:37:13,887][flwr][ERROR] - [36mray::DefaultActor.run()[39m (pid=92187, ip=127.0.0.1, actor_id=99ee256a1db7a48f08793abb01000000, repr=<flwr.simulation.ray_transport.ray_actor.DefaultActor object at 0x13049a050>)
  File "/Users/saisatyajonnalagadda/current_projects/carb_aware_model_adaption_FL/main2.py", line 116, in client_fn
    trainloader=trainloaders[client_id],
IndexError: list index out of range

The above exception was the direct cause of the following exception:

[36mray::DefaultActor.run()[39m (pid=92187, ip=127.0.0.1, actor_id=99ee256a1db7a48f08793abb01000000, repr=<flwr.simulation.ray_transport.ray_actor.DefaultActor object at 0x13049a050>)
  File "/Users/saisatyajonnalagadda/miniforge3/envs/carbFL/lib/python3.10/site-packages/flwr/simulation/ray_transport/ray_actor.py", line 84, in run
    raise ClientException(str(message)) from ex
flwr.simulation.ray_transport.ray_actor.ClientException: 
>>>>>>>A ClientException occurred.('\n\tSomething went wrong when running your client workload.\n\tClient 91_San Francisco_large crashed when the DefaultActor was running its workload.\n\tException triggered on the client side: Traceback (most recent call last):\n  File "/Users/saisatyajonnalagadda/miniforge3/envs/carbFL/lib/python3.10/site-packages/flwr/simulation/ray_transport/ray_actor.py", line 70, in run\n    client = check_clientfn_returns_client(client_fn(cid))\n  File "/Users/saisatyajonnalagadda/current_projects/carb_aware_model_adaption_FL/main2.py", line 116, in client_fn\n    trainloader=trainloaders[client_id],\nIndexError: list index out of range\n',)
[2024-06-25 12:37:35,209][flwr][ERROR] - Traceback (most recent call last):
  File "/Users/saisatyajonnalagadda/miniforge3/envs/carbFL/lib/python3.10/site-packages/flwr/simulation/ray_transport/ray_client_proxy.py", line 138, in _submit_job
    res = self.actor_pool.get_client_result(self.cid, timeout)
  File "/Users/saisatyajonnalagadda/miniforge3/envs/carbFL/lib/python3.10/site-packages/flwr/simulation/ray_transport/ray_actor.py", line 414, in get_client_result
    return self._fetch_future_result(cid)
  File "/Users/saisatyajonnalagadda/miniforge3/envs/carbFL/lib/python3.10/site-packages/flwr/simulation/ray_transport/ray_actor.py", line 300, in _fetch_future_result
    res_cid, res = ray.get(future)  # type: (str, ClientRes)
  File "/Users/saisatyajonnalagadda/miniforge3/envs/carbFL/lib/python3.10/site-packages/ray/_private/auto_init_hook.py", line 24, in auto_init_wrapper
    return fn(*args, **kwargs)
  File "/Users/saisatyajonnalagadda/miniforge3/envs/carbFL/lib/python3.10/site-packages/ray/_private/client_mode_hook.py", line 103, in wrapper
    return func(*args, **kwargs)
  File "/Users/saisatyajonnalagadda/miniforge3/envs/carbFL/lib/python3.10/site-packages/ray/_private/worker.py", line 2524, in get
    raise value.as_instanceof_cause()
ray.exceptions.RayTaskError(ClientException): [36mray::DefaultActor.run()[39m (pid=92181, ip=127.0.0.1, actor_id=2b752e872e965a5b9b6e33ef01000000, repr=<flwr.simulation.ray_transport.ray_actor.DefaultActor object at 0x10ae0e050>)
  File "/Users/saisatyajonnalagadda/current_projects/carb_aware_model_adaption_FL/main2.py", line 116, in client_fn
    trainloader=trainloaders[client_id],
IndexError: list index out of range

The above exception was the direct cause of the following exception:

[36mray::DefaultActor.run()[39m (pid=92181, ip=127.0.0.1, actor_id=2b752e872e965a5b9b6e33ef01000000, repr=<flwr.simulation.ray_transport.ray_actor.DefaultActor object at 0x10ae0e050>)
  File "/Users/saisatyajonnalagadda/miniforge3/envs/carbFL/lib/python3.10/site-packages/flwr/simulation/ray_transport/ray_actor.py", line 84, in run
    raise ClientException(str(message)) from ex
flwr.simulation.ray_transport.ray_actor.ClientException: 
>>>>>>>A ClientException occurred.('\n\tSomething went wrong when running your client workload.\n\tClient 87_San Francisco_mid crashed when the DefaultActor was running its workload.\n\tException triggered on the client side: Traceback (most recent call last):\n  File "/Users/saisatyajonnalagadda/miniforge3/envs/carbFL/lib/python3.10/site-packages/flwr/simulation/ray_transport/ray_actor.py", line 70, in run\n    client = check_clientfn_returns_client(client_fn(cid))\n  File "/Users/saisatyajonnalagadda/current_projects/carb_aware_model_adaption_FL/main2.py", line 116, in client_fn\n    trainloader=trainloaders[client_id],\nIndexError: list index out of range\n',)

[2024-06-25 12:37:35,222][flwr][ERROR] - Traceback (most recent call last):
  File "/Users/saisatyajonnalagadda/miniforge3/envs/carbFL/lib/python3.10/site-packages/flwr/simulation/ray_transport/ray_client_proxy.py", line 138, in _submit_job
    res = self.actor_pool.get_client_result(self.cid, timeout)
  File "/Users/saisatyajonnalagadda/miniforge3/envs/carbFL/lib/python3.10/site-packages/flwr/simulation/ray_transport/ray_actor.py", line 414, in get_client_result
    return self._fetch_future_result(cid)
  File "/Users/saisatyajonnalagadda/miniforge3/envs/carbFL/lib/python3.10/site-packages/flwr/simulation/ray_transport/ray_actor.py", line 300, in _fetch_future_result
    res_cid, res = ray.get(future)  # type: (str, ClientRes)
  File "/Users/saisatyajonnalagadda/miniforge3/envs/carbFL/lib/python3.10/site-packages/ray/_private/auto_init_hook.py", line 24, in auto_init_wrapper
    return fn(*args, **kwargs)
  File "/Users/saisatyajonnalagadda/miniforge3/envs/carbFL/lib/python3.10/site-packages/ray/_private/client_mode_hook.py", line 103, in wrapper
    return func(*args, **kwargs)
  File "/Users/saisatyajonnalagadda/miniforge3/envs/carbFL/lib/python3.10/site-packages/ray/_private/worker.py", line 2524, in get
    raise value.as_instanceof_cause()
ray.exceptions.RayTaskError(ClientException): [36mray::DefaultActor.run()[39m (pid=92181, ip=127.0.0.1, actor_id=2b752e872e965a5b9b6e33ef01000000, repr=<flwr.simulation.ray_transport.ray_actor.DefaultActor object at 0x10ae0e050>)
  File "/Users/saisatyajonnalagadda/current_projects/carb_aware_model_adaption_FL/main2.py", line 116, in client_fn
    trainloader=trainloaders[client_id],
IndexError: list index out of range

The above exception was the direct cause of the following exception:

[36mray::DefaultActor.run()[39m (pid=92181, ip=127.0.0.1, actor_id=2b752e872e965a5b9b6e33ef01000000, repr=<flwr.simulation.ray_transport.ray_actor.DefaultActor object at 0x10ae0e050>)
  File "/Users/saisatyajonnalagadda/miniforge3/envs/carbFL/lib/python3.10/site-packages/flwr/simulation/ray_transport/ray_actor.py", line 84, in run
    raise ClientException(str(message)) from ex
flwr.simulation.ray_transport.ray_actor.ClientException: 
>>>>>>>A ClientException occurred.('\n\tSomething went wrong when running your client workload.\n\tClient 56_Hong Kong_mid crashed when the DefaultActor was running its workload.\n\tException triggered on the client side: Traceback (most recent call last):\n  File "/Users/saisatyajonnalagadda/miniforge3/envs/carbFL/lib/python3.10/site-packages/flwr/simulation/ray_transport/ray_actor.py", line 70, in run\n    client = check_clientfn_returns_client(client_fn(cid))\n  File "/Users/saisatyajonnalagadda/current_projects/carb_aware_model_adaption_FL/main2.py", line 116, in client_fn\n    trainloader=trainloaders[client_id],\nIndexError: list index out of range\n',)

[2024-06-25 12:37:35,222][flwr][ERROR] - Traceback (most recent call last):
  File "/Users/saisatyajonnalagadda/miniforge3/envs/carbFL/lib/python3.10/site-packages/flwr/simulation/ray_transport/ray_client_proxy.py", line 138, in _submit_job
    res = self.actor_pool.get_client_result(self.cid, timeout)
  File "/Users/saisatyajonnalagadda/miniforge3/envs/carbFL/lib/python3.10/site-packages/flwr/simulation/ray_transport/ray_actor.py", line 414, in get_client_result
    return self._fetch_future_result(cid)
  File "/Users/saisatyajonnalagadda/miniforge3/envs/carbFL/lib/python3.10/site-packages/flwr/simulation/ray_transport/ray_actor.py", line 300, in _fetch_future_result
    res_cid, res = ray.get(future)  # type: (str, ClientRes)
  File "/Users/saisatyajonnalagadda/miniforge3/envs/carbFL/lib/python3.10/site-packages/ray/_private/auto_init_hook.py", line 24, in auto_init_wrapper
    return fn(*args, **kwargs)
  File "/Users/saisatyajonnalagadda/miniforge3/envs/carbFL/lib/python3.10/site-packages/ray/_private/client_mode_hook.py", line 103, in wrapper
    return func(*args, **kwargs)
  File "/Users/saisatyajonnalagadda/miniforge3/envs/carbFL/lib/python3.10/site-packages/ray/_private/worker.py", line 2524, in get
    raise value.as_instanceof_cause()
ray.exceptions.RayTaskError(ClientException): [36mray::DefaultActor.run()[39m (pid=92187, ip=127.0.0.1, actor_id=99ee256a1db7a48f08793abb01000000, repr=<flwr.simulation.ray_transport.ray_actor.DefaultActor object at 0x13049a050>)
  File "/Users/saisatyajonnalagadda/current_projects/carb_aware_model_adaption_FL/main2.py", line 116, in client_fn
    trainloader=trainloaders[client_id],
IndexError: list index out of range

The above exception was the direct cause of the following exception:

[36mray::DefaultActor.run()[39m (pid=92187, ip=127.0.0.1, actor_id=99ee256a1db7a48f08793abb01000000, repr=<flwr.simulation.ray_transport.ray_actor.DefaultActor object at 0x13049a050>)
  File "/Users/saisatyajonnalagadda/miniforge3/envs/carbFL/lib/python3.10/site-packages/flwr/simulation/ray_transport/ray_actor.py", line 84, in run
    raise ClientException(str(message)) from ex
flwr.simulation.ray_transport.ray_actor.ClientException: 
>>>>>>>A ClientException occurred.('\n\tSomething went wrong when running your client workload.\n\tClient 71_Sydney_mid crashed when the DefaultActor was running its workload.\n\tException triggered on the client side: Traceback (most recent call last):\n  File "/Users/saisatyajonnalagadda/miniforge3/envs/carbFL/lib/python3.10/site-packages/flwr/simulation/ray_transport/ray_actor.py", line 70, in run\n    client = check_clientfn_returns_client(client_fn(cid))\n  File "/Users/saisatyajonnalagadda/current_projects/carb_aware_model_adaption_FL/main2.py", line 116, in client_fn\n    trainloader=trainloaders[client_id],\nIndexError: list index out of range\n',)

[2024-06-25 12:37:35,236][flwr][ERROR] - [36mray::DefaultActor.run()[39m (pid=92181, ip=127.0.0.1, actor_id=2b752e872e965a5b9b6e33ef01000000, repr=<flwr.simulation.ray_transport.ray_actor.DefaultActor object at 0x10ae0e050>)
  File "/Users/saisatyajonnalagadda/current_projects/carb_aware_model_adaption_FL/main2.py", line 116, in client_fn
    trainloader=trainloaders[client_id],
IndexError: list index out of range

The above exception was the direct cause of the following exception:

[36mray::DefaultActor.run()[39m (pid=92181, ip=127.0.0.1, actor_id=2b752e872e965a5b9b6e33ef01000000, repr=<flwr.simulation.ray_transport.ray_actor.DefaultActor object at 0x10ae0e050>)
  File "/Users/saisatyajonnalagadda/miniforge3/envs/carbFL/lib/python3.10/site-packages/flwr/simulation/ray_transport/ray_actor.py", line 84, in run
    raise ClientException(str(message)) from ex
flwr.simulation.ray_transport.ray_actor.ClientException: 
>>>>>>>A ClientException occurred.('\n\tSomething went wrong when running your client workload.\n\tClient 87_San Francisco_mid crashed when the DefaultActor was running its workload.\n\tException triggered on the client side: Traceback (most recent call last):\n  File "/Users/saisatyajonnalagadda/miniforge3/envs/carbFL/lib/python3.10/site-packages/flwr/simulation/ray_transport/ray_actor.py", line 70, in run\n    client = check_clientfn_returns_client(client_fn(cid))\n  File "/Users/saisatyajonnalagadda/current_projects/carb_aware_model_adaption_FL/main2.py", line 116, in client_fn\n    trainloader=trainloaders[client_id],\nIndexError: list index out of range\n',)
[2024-06-25 12:37:35,242][flwr][ERROR] - [36mray::DefaultActor.run()[39m (pid=92181, ip=127.0.0.1, actor_id=2b752e872e965a5b9b6e33ef01000000, repr=<flwr.simulation.ray_transport.ray_actor.DefaultActor object at 0x10ae0e050>)
  File "/Users/saisatyajonnalagadda/current_projects/carb_aware_model_adaption_FL/main2.py", line 116, in client_fn
    trainloader=trainloaders[client_id],
IndexError: list index out of range

The above exception was the direct cause of the following exception:

[36mray::DefaultActor.run()[39m (pid=92181, ip=127.0.0.1, actor_id=2b752e872e965a5b9b6e33ef01000000, repr=<flwr.simulation.ray_transport.ray_actor.DefaultActor object at 0x10ae0e050>)
  File "/Users/saisatyajonnalagadda/miniforge3/envs/carbFL/lib/python3.10/site-packages/flwr/simulation/ray_transport/ray_actor.py", line 84, in run
    raise ClientException(str(message)) from ex
flwr.simulation.ray_transport.ray_actor.ClientException: 
>>>>>>>A ClientException occurred.('\n\tSomething went wrong when running your client workload.\n\tClient 56_Hong Kong_mid crashed when the DefaultActor was running its workload.\n\tException triggered on the client side: Traceback (most recent call last):\n  File "/Users/saisatyajonnalagadda/miniforge3/envs/carbFL/lib/python3.10/site-packages/flwr/simulation/ray_transport/ray_actor.py", line 70, in run\n    client = check_clientfn_returns_client(client_fn(cid))\n  File "/Users/saisatyajonnalagadda/current_projects/carb_aware_model_adaption_FL/main2.py", line 116, in client_fn\n    trainloader=trainloaders[client_id],\nIndexError: list index out of range\n',)
[2024-06-25 12:37:35,261][flwr][ERROR] - [36mray::DefaultActor.run()[39m (pid=92187, ip=127.0.0.1, actor_id=99ee256a1db7a48f08793abb01000000, repr=<flwr.simulation.ray_transport.ray_actor.DefaultActor object at 0x13049a050>)
  File "/Users/saisatyajonnalagadda/current_projects/carb_aware_model_adaption_FL/main2.py", line 116, in client_fn
    trainloader=trainloaders[client_id],
IndexError: list index out of range

The above exception was the direct cause of the following exception:

[36mray::DefaultActor.run()[39m (pid=92187, ip=127.0.0.1, actor_id=99ee256a1db7a48f08793abb01000000, repr=<flwr.simulation.ray_transport.ray_actor.DefaultActor object at 0x13049a050>)
  File "/Users/saisatyajonnalagadda/miniforge3/envs/carbFL/lib/python3.10/site-packages/flwr/simulation/ray_transport/ray_actor.py", line 84, in run
    raise ClientException(str(message)) from ex
flwr.simulation.ray_transport.ray_actor.ClientException: 
>>>>>>>A ClientException occurred.('\n\tSomething went wrong when running your client workload.\n\tClient 71_Sydney_mid crashed when the DefaultActor was running its workload.\n\tException triggered on the client side: Traceback (most recent call last):\n  File "/Users/saisatyajonnalagadda/miniforge3/envs/carbFL/lib/python3.10/site-packages/flwr/simulation/ray_transport/ray_actor.py", line 70, in run\n    client = check_clientfn_returns_client(client_fn(cid))\n  File "/Users/saisatyajonnalagadda/current_projects/carb_aware_model_adaption_FL/main2.py", line 116, in client_fn\n    trainloader=trainloaders[client_id],\nIndexError: list index out of range\n',)
[2024-06-25 12:37:54,952][flwr][ERROR] - Traceback (most recent call last):
  File "/Users/saisatyajonnalagadda/miniforge3/envs/carbFL/lib/python3.10/site-packages/flwr/simulation/ray_transport/ray_client_proxy.py", line 138, in _submit_job
    res = self.actor_pool.get_client_result(self.cid, timeout)
  File "/Users/saisatyajonnalagadda/miniforge3/envs/carbFL/lib/python3.10/site-packages/flwr/simulation/ray_transport/ray_actor.py", line 408, in get_client_result
    self.process_unordered_future(timeout=timeout)
  File "/Users/saisatyajonnalagadda/miniforge3/envs/carbFL/lib/python3.10/site-packages/flwr/simulation/ray_transport/ray_actor.py", line 392, in process_unordered_future
    self._return_actor(actor)  # type: ignore
  File "/Users/saisatyajonnalagadda/miniforge3/envs/carbFL/lib/python3.10/site-packages/ray/util/actor_pool.py", line 366, in _return_actor
    self.submit(*self._pending_submits.pop(0))
  File "/Users/saisatyajonnalagadda/miniforge3/envs/carbFL/lib/python3.10/site-packages/flwr/simulation/ray_transport/ray_actor.py", line 243, in submit
    future = fn(actor, client_fn, job_fn, cid)
  File "/Users/saisatyajonnalagadda/miniforge3/envs/carbFL/lib/python3.10/site-packages/flwr/simulation/ray_transport/ray_client_proxy.py", line 135, in <lambda>
    lambda a, c_fn, j_fn, cid: a.run.remote(c_fn, j_fn, cid),
  File "/Users/saisatyajonnalagadda/miniforge3/envs/carbFL/lib/python3.10/site-packages/ray/actor.py", line 144, in remote
    return self._remote(args, kwargs)
  File "/Users/saisatyajonnalagadda/miniforge3/envs/carbFL/lib/python3.10/site-packages/ray/util/tracing/tracing_helper.py", line 423, in _start_span
    return method(self, args, kwargs, *_args, **_kwargs)
  File "/Users/saisatyajonnalagadda/miniforge3/envs/carbFL/lib/python3.10/site-packages/ray/actor.py", line 190, in _remote
    return invocation(args, kwargs)
  File "/Users/saisatyajonnalagadda/miniforge3/envs/carbFL/lib/python3.10/site-packages/ray/actor.py", line 177, in invocation
    return actor._actor_method_call(
  File "/Users/saisatyajonnalagadda/miniforge3/envs/carbFL/lib/python3.10/site-packages/ray/actor.py", line 1175, in _actor_method_call
    object_refs = worker.core_worker.submit_actor_task(
  File "python/ray/_raylet.pyx", line 3350, in ray._raylet.CoreWorker.submit_actor_task
  File "python/ray/_raylet.pyx", line 3355, in ray._raylet.CoreWorker.submit_actor_task
  File "python/ray/_raylet.pyx", line 649, in ray._raylet.prepare_args_and_increment_put_refs
  File "python/ray/_raylet.pyx", line 640, in ray._raylet.prepare_args_and_increment_put_refs
  File "python/ray/_raylet.pyx", line 734, in ray._raylet.prepare_args_internal
  File "python/ray/_raylet.pyx", line 2939, in ray._raylet.CoreWorker.put_serialized_object_and_increment_local_ref
  File "python/ray/_raylet.pyx", line 2831, in ray._raylet.CoreWorker._create_put_buffer
  File "python/ray/_raylet.pyx", line 396, in ray._raylet.check_status
ray.exceptions.OutOfDiskError: Local disk is full
The object cannot be created because the local object store is full and the local disk's utilization is over capacity (95% by default).Tip: Use `df` on this node to check disk usage and `ray memory` to check object store memory usage.

[2024-06-25 12:37:54,979][flwr][ERROR] - Local disk is full
The object cannot be created because the local object store is full and the local disk's utilization is over capacity (95% by default).Tip: Use `df` on this node to check disk usage and `ray memory` to check object store memory usage.
[2024-06-25 12:37:59,296][flwr][ERROR] - Traceback (most recent call last):
  File "/Users/saisatyajonnalagadda/miniforge3/envs/carbFL/lib/python3.10/site-packages/flwr/simulation/ray_transport/ray_client_proxy.py", line 138, in _submit_job
    res = self.actor_pool.get_client_result(self.cid, timeout)
  File "/Users/saisatyajonnalagadda/miniforge3/envs/carbFL/lib/python3.10/site-packages/flwr/simulation/ray_transport/ray_actor.py", line 414, in get_client_result
    return self._fetch_future_result(cid)
  File "/Users/saisatyajonnalagadda/miniforge3/envs/carbFL/lib/python3.10/site-packages/flwr/simulation/ray_transport/ray_actor.py", line 300, in _fetch_future_result
    res_cid, res = ray.get(future)  # type: (str, ClientRes)
  File "/Users/saisatyajonnalagadda/miniforge3/envs/carbFL/lib/python3.10/site-packages/ray/_private/auto_init_hook.py", line 24, in auto_init_wrapper
    return fn(*args, **kwargs)
  File "/Users/saisatyajonnalagadda/miniforge3/envs/carbFL/lib/python3.10/site-packages/ray/_private/client_mode_hook.py", line 103, in wrapper
    return func(*args, **kwargs)
  File "/Users/saisatyajonnalagadda/miniforge3/envs/carbFL/lib/python3.10/site-packages/ray/_private/worker.py", line 2524, in get
    raise value.as_instanceof_cause()
ray.exceptions.RayTaskError(ClientException): [36mray::DefaultActor.run()[39m (pid=92183, ip=127.0.0.1, actor_id=7029cdde1d7ee8a4a716634101000000, repr=<flwr.simulation.ray_transport.ray_actor.DefaultActor object at 0x1208fe0b0>)
  File "/Users/saisatyajonnalagadda/current_projects/carb_aware_model_adaption_FL/main2.py", line 116, in client_fn
    trainloader=trainloaders[client_id],
IndexError: list index out of range

The above exception was the direct cause of the following exception:

[36mray::DefaultActor.run()[39m (pid=92183, ip=127.0.0.1, actor_id=7029cdde1d7ee8a4a716634101000000, repr=<flwr.simulation.ray_transport.ray_actor.DefaultActor object at 0x1208fe0b0>)
  File "/Users/saisatyajonnalagadda/miniforge3/envs/carbFL/lib/python3.10/site-packages/flwr/simulation/ray_transport/ray_actor.py", line 84, in run
    raise ClientException(str(message)) from ex
flwr.simulation.ray_transport.ray_actor.ClientException: 
>>>>>>>A ClientException occurred.('\n\tSomething went wrong when running your client workload.\n\tClient 78_San Francisco_mid crashed when the DefaultActor was running its workload.\n\tException triggered on the client side: Traceback (most recent call last):\n  File "/Users/saisatyajonnalagadda/miniforge3/envs/carbFL/lib/python3.10/site-packages/flwr/simulation/ray_transport/ray_actor.py", line 70, in run\n    client = check_clientfn_returns_client(client_fn(cid))\n  File "/Users/saisatyajonnalagadda/current_projects/carb_aware_model_adaption_FL/main2.py", line 116, in client_fn\n    trainloader=trainloaders[client_id],\nIndexError: list index out of range\n',)

[2024-06-25 12:37:59,299][flwr][ERROR] - Traceback (most recent call last):
  File "/Users/saisatyajonnalagadda/miniforge3/envs/carbFL/lib/python3.10/site-packages/flwr/simulation/ray_transport/ray_client_proxy.py", line 138, in _submit_job
    res = self.actor_pool.get_client_result(self.cid, timeout)
  File "/Users/saisatyajonnalagadda/miniforge3/envs/carbFL/lib/python3.10/site-packages/flwr/simulation/ray_transport/ray_actor.py", line 408, in get_client_result
    self.process_unordered_future(timeout=timeout)
  File "/Users/saisatyajonnalagadda/miniforge3/envs/carbFL/lib/python3.10/site-packages/flwr/simulation/ray_transport/ray_actor.py", line 392, in process_unordered_future
    self._return_actor(actor)  # type: ignore
  File "/Users/saisatyajonnalagadda/miniforge3/envs/carbFL/lib/python3.10/site-packages/ray/util/actor_pool.py", line 366, in _return_actor
    self.submit(*self._pending_submits.pop(0))
  File "/Users/saisatyajonnalagadda/miniforge3/envs/carbFL/lib/python3.10/site-packages/flwr/simulation/ray_transport/ray_actor.py", line 243, in submit
    future = fn(actor, client_fn, job_fn, cid)
  File "/Users/saisatyajonnalagadda/miniforge3/envs/carbFL/lib/python3.10/site-packages/flwr/simulation/ray_transport/ray_client_proxy.py", line 135, in <lambda>
    lambda a, c_fn, j_fn, cid: a.run.remote(c_fn, j_fn, cid),
  File "/Users/saisatyajonnalagadda/miniforge3/envs/carbFL/lib/python3.10/site-packages/ray/actor.py", line 144, in remote
    return self._remote(args, kwargs)
  File "/Users/saisatyajonnalagadda/miniforge3/envs/carbFL/lib/python3.10/site-packages/ray/util/tracing/tracing_helper.py", line 423, in _start_span
    return method(self, args, kwargs, *_args, **_kwargs)
  File "/Users/saisatyajonnalagadda/miniforge3/envs/carbFL/lib/python3.10/site-packages/ray/actor.py", line 190, in _remote
    return invocation(args, kwargs)
  File "/Users/saisatyajonnalagadda/miniforge3/envs/carbFL/lib/python3.10/site-packages/ray/actor.py", line 177, in invocation
    return actor._actor_method_call(
  File "/Users/saisatyajonnalagadda/miniforge3/envs/carbFL/lib/python3.10/site-packages/ray/actor.py", line 1175, in _actor_method_call
    object_refs = worker.core_worker.submit_actor_task(
  File "python/ray/_raylet.pyx", line 3350, in ray._raylet.CoreWorker.submit_actor_task
  File "python/ray/_raylet.pyx", line 3355, in ray._raylet.CoreWorker.submit_actor_task
  File "python/ray/_raylet.pyx", line 649, in ray._raylet.prepare_args_and_increment_put_refs
  File "python/ray/_raylet.pyx", line 640, in ray._raylet.prepare_args_and_increment_put_refs
  File "python/ray/_raylet.pyx", line 734, in ray._raylet.prepare_args_internal
  File "python/ray/_raylet.pyx", line 2939, in ray._raylet.CoreWorker.put_serialized_object_and_increment_local_ref
  File "python/ray/_raylet.pyx", line 2831, in ray._raylet.CoreWorker._create_put_buffer
  File "python/ray/_raylet.pyx", line 396, in ray._raylet.check_status
ray.exceptions.OutOfDiskError: Local disk is full
The object cannot be created because the local object store is full and the local disk's utilization is over capacity (95% by default).Tip: Use `df` on this node to check disk usage and `ray memory` to check object store memory usage.

[2024-06-25 12:37:59,324][flwr][ERROR] - [36mray::DefaultActor.run()[39m (pid=92183, ip=127.0.0.1, actor_id=7029cdde1d7ee8a4a716634101000000, repr=<flwr.simulation.ray_transport.ray_actor.DefaultActor object at 0x1208fe0b0>)
  File "/Users/saisatyajonnalagadda/current_projects/carb_aware_model_adaption_FL/main2.py", line 116, in client_fn
    trainloader=trainloaders[client_id],
IndexError: list index out of range

The above exception was the direct cause of the following exception:

[36mray::DefaultActor.run()[39m (pid=92183, ip=127.0.0.1, actor_id=7029cdde1d7ee8a4a716634101000000, repr=<flwr.simulation.ray_transport.ray_actor.DefaultActor object at 0x1208fe0b0>)
  File "/Users/saisatyajonnalagadda/miniforge3/envs/carbFL/lib/python3.10/site-packages/flwr/simulation/ray_transport/ray_actor.py", line 84, in run
    raise ClientException(str(message)) from ex
flwr.simulation.ray_transport.ray_actor.ClientException: 
>>>>>>>A ClientException occurred.('\n\tSomething went wrong when running your client workload.\n\tClient 78_San Francisco_mid crashed when the DefaultActor was running its workload.\n\tException triggered on the client side: Traceback (most recent call last):\n  File "/Users/saisatyajonnalagadda/miniforge3/envs/carbFL/lib/python3.10/site-packages/flwr/simulation/ray_transport/ray_actor.py", line 70, in run\n    client = check_clientfn_returns_client(client_fn(cid))\n  File "/Users/saisatyajonnalagadda/current_projects/carb_aware_model_adaption_FL/main2.py", line 116, in client_fn\n    trainloader=trainloaders[client_id],\nIndexError: list index out of range\n',)
[2024-06-25 12:37:59,343][flwr][ERROR] - Local disk is full
The object cannot be created because the local object store is full and the local disk's utilization is over capacity (95% by default).Tip: Use `df` on this node to check disk usage and `ray memory` to check object store memory usage.
[2024-06-25 12:38:12,973][flwr][ERROR] - Traceback (most recent call last):
  File "/Users/saisatyajonnalagadda/miniforge3/envs/carbFL/lib/python3.10/site-packages/flwr/simulation/ray_transport/ray_client_proxy.py", line 138, in _submit_job
    res = self.actor_pool.get_client_result(self.cid, timeout)
  File "/Users/saisatyajonnalagadda/miniforge3/envs/carbFL/lib/python3.10/site-packages/flwr/simulation/ray_transport/ray_actor.py", line 414, in get_client_result
    return self._fetch_future_result(cid)
  File "/Users/saisatyajonnalagadda/miniforge3/envs/carbFL/lib/python3.10/site-packages/flwr/simulation/ray_transport/ray_actor.py", line 300, in _fetch_future_result
    res_cid, res = ray.get(future)  # type: (str, ClientRes)
  File "/Users/saisatyajonnalagadda/miniforge3/envs/carbFL/lib/python3.10/site-packages/ray/_private/auto_init_hook.py", line 24, in auto_init_wrapper
    return fn(*args, **kwargs)
  File "/Users/saisatyajonnalagadda/miniforge3/envs/carbFL/lib/python3.10/site-packages/ray/_private/client_mode_hook.py", line 103, in wrapper
    return func(*args, **kwargs)
  File "/Users/saisatyajonnalagadda/miniforge3/envs/carbFL/lib/python3.10/site-packages/ray/_private/worker.py", line 2524, in get
    raise value.as_instanceof_cause()
ray.exceptions.RayTaskError(ClientException): [36mray::DefaultActor.run()[39m (pid=92187, ip=127.0.0.1, actor_id=99ee256a1db7a48f08793abb01000000, repr=<flwr.simulation.ray_transport.ray_actor.DefaultActor object at 0x13049a050>)
  File "/Users/saisatyajonnalagadda/current_projects/carb_aware_model_adaption_FL/main2.py", line 116, in client_fn
    trainloader=trainloaders[client_id],
IndexError: list index out of range

The above exception was the direct cause of the following exception:

[36mray::DefaultActor.run()[39m (pid=92187, ip=127.0.0.1, actor_id=99ee256a1db7a48f08793abb01000000, repr=<flwr.simulation.ray_transport.ray_actor.DefaultActor object at 0x13049a050>)
  File "/Users/saisatyajonnalagadda/miniforge3/envs/carbFL/lib/python3.10/site-packages/flwr/simulation/ray_transport/ray_actor.py", line 84, in run
    raise ClientException(str(message)) from ex
flwr.simulation.ray_transport.ray_actor.ClientException: 
>>>>>>>A ClientException occurred.('\n\tSomething went wrong when running your client workload.\n\tClient 73_Mexico City_small crashed when the DefaultActor was running its workload.\n\tException triggered on the client side: Traceback (most recent call last):\n  File "/Users/saisatyajonnalagadda/miniforge3/envs/carbFL/lib/python3.10/site-packages/flwr/simulation/ray_transport/ray_actor.py", line 70, in run\n    client = check_clientfn_returns_client(client_fn(cid))\n  File "/Users/saisatyajonnalagadda/current_projects/carb_aware_model_adaption_FL/main2.py", line 116, in client_fn\n    trainloader=trainloaders[client_id],\nIndexError: list index out of range\n',)

[2024-06-25 12:38:12,976][flwr][ERROR] - Traceback (most recent call last):
  File "/Users/saisatyajonnalagadda/miniforge3/envs/carbFL/lib/python3.10/site-packages/flwr/simulation/ray_transport/ray_client_proxy.py", line 138, in _submit_job
    res = self.actor_pool.get_client_result(self.cid, timeout)
  File "/Users/saisatyajonnalagadda/miniforge3/envs/carbFL/lib/python3.10/site-packages/flwr/simulation/ray_transport/ray_actor.py", line 414, in get_client_result
    return self._fetch_future_result(cid)
  File "/Users/saisatyajonnalagadda/miniforge3/envs/carbFL/lib/python3.10/site-packages/flwr/simulation/ray_transport/ray_actor.py", line 300, in _fetch_future_result
    res_cid, res = ray.get(future)  # type: (str, ClientRes)
  File "/Users/saisatyajonnalagadda/miniforge3/envs/carbFL/lib/python3.10/site-packages/ray/_private/auto_init_hook.py", line 24, in auto_init_wrapper
    return fn(*args, **kwargs)
  File "/Users/saisatyajonnalagadda/miniforge3/envs/carbFL/lib/python3.10/site-packages/ray/_private/client_mode_hook.py", line 103, in wrapper
    return func(*args, **kwargs)
  File "/Users/saisatyajonnalagadda/miniforge3/envs/carbFL/lib/python3.10/site-packages/ray/_private/worker.py", line 2524, in get
    raise value.as_instanceof_cause()
ray.exceptions.RayTaskError(ClientException): [36mray::DefaultActor.run()[39m (pid=92187, ip=127.0.0.1, actor_id=99ee256a1db7a48f08793abb01000000, repr=<flwr.simulation.ray_transport.ray_actor.DefaultActor object at 0x13049a050>)
  File "/Users/saisatyajonnalagadda/current_projects/carb_aware_model_adaption_FL/main2.py", line 116, in client_fn
    trainloader=trainloaders[client_id],
IndexError: list index out of range

The above exception was the direct cause of the following exception:

[36mray::DefaultActor.run()[39m (pid=92187, ip=127.0.0.1, actor_id=99ee256a1db7a48f08793abb01000000, repr=<flwr.simulation.ray_transport.ray_actor.DefaultActor object at 0x13049a050>)
  File "/Users/saisatyajonnalagadda/miniforge3/envs/carbFL/lib/python3.10/site-packages/flwr/simulation/ray_transport/ray_actor.py", line 84, in run
    raise ClientException(str(message)) from ex
flwr.simulation.ray_transport.ray_actor.ClientException: 
>>>>>>>A ClientException occurred.('\n\tSomething went wrong when running your client workload.\n\tClient 61_Mexico City_small crashed when the DefaultActor was running its workload.\n\tException triggered on the client side: Traceback (most recent call last):\n  File "/Users/saisatyajonnalagadda/miniforge3/envs/carbFL/lib/python3.10/site-packages/flwr/simulation/ray_transport/ray_actor.py", line 70, in run\n    client = check_clientfn_returns_client(client_fn(cid))\n  File "/Users/saisatyajonnalagadda/current_projects/carb_aware_model_adaption_FL/main2.py", line 116, in client_fn\n    trainloader=trainloaders[client_id],\nIndexError: list index out of range\n',)

[2024-06-25 12:38:12,990][flwr][ERROR] - [36mray::DefaultActor.run()[39m (pid=92187, ip=127.0.0.1, actor_id=99ee256a1db7a48f08793abb01000000, repr=<flwr.simulation.ray_transport.ray_actor.DefaultActor object at 0x13049a050>)
  File "/Users/saisatyajonnalagadda/current_projects/carb_aware_model_adaption_FL/main2.py", line 116, in client_fn
    trainloader=trainloaders[client_id],
IndexError: list index out of range

The above exception was the direct cause of the following exception:

[36mray::DefaultActor.run()[39m (pid=92187, ip=127.0.0.1, actor_id=99ee256a1db7a48f08793abb01000000, repr=<flwr.simulation.ray_transport.ray_actor.DefaultActor object at 0x13049a050>)
  File "/Users/saisatyajonnalagadda/miniforge3/envs/carbFL/lib/python3.10/site-packages/flwr/simulation/ray_transport/ray_actor.py", line 84, in run
    raise ClientException(str(message)) from ex
flwr.simulation.ray_transport.ray_actor.ClientException: 
>>>>>>>A ClientException occurred.('\n\tSomething went wrong when running your client workload.\n\tClient 73_Mexico City_small crashed when the DefaultActor was running its workload.\n\tException triggered on the client side: Traceback (most recent call last):\n  File "/Users/saisatyajonnalagadda/miniforge3/envs/carbFL/lib/python3.10/site-packages/flwr/simulation/ray_transport/ray_actor.py", line 70, in run\n    client = check_clientfn_returns_client(client_fn(cid))\n  File "/Users/saisatyajonnalagadda/current_projects/carb_aware_model_adaption_FL/main2.py", line 116, in client_fn\n    trainloader=trainloaders[client_id],\nIndexError: list index out of range\n',)
[2024-06-25 12:38:13,040][flwr][ERROR] - [36mray::DefaultActor.run()[39m (pid=92187, ip=127.0.0.1, actor_id=99ee256a1db7a48f08793abb01000000, repr=<flwr.simulation.ray_transport.ray_actor.DefaultActor object at 0x13049a050>)
  File "/Users/saisatyajonnalagadda/current_projects/carb_aware_model_adaption_FL/main2.py", line 116, in client_fn
    trainloader=trainloaders[client_id],
IndexError: list index out of range

The above exception was the direct cause of the following exception:

[36mray::DefaultActor.run()[39m (pid=92187, ip=127.0.0.1, actor_id=99ee256a1db7a48f08793abb01000000, repr=<flwr.simulation.ray_transport.ray_actor.DefaultActor object at 0x13049a050>)
  File "/Users/saisatyajonnalagadda/miniforge3/envs/carbFL/lib/python3.10/site-packages/flwr/simulation/ray_transport/ray_actor.py", line 84, in run
    raise ClientException(str(message)) from ex
flwr.simulation.ray_transport.ray_actor.ClientException: 
>>>>>>>A ClientException occurred.('\n\tSomething went wrong when running your client workload.\n\tClient 61_Mexico City_small crashed when the DefaultActor was running its workload.\n\tException triggered on the client side: Traceback (most recent call last):\n  File "/Users/saisatyajonnalagadda/miniforge3/envs/carbFL/lib/python3.10/site-packages/flwr/simulation/ray_transport/ray_actor.py", line 70, in run\n    client = check_clientfn_returns_client(client_fn(cid))\n  File "/Users/saisatyajonnalagadda/current_projects/carb_aware_model_adaption_FL/main2.py", line 116, in client_fn\n    trainloader=trainloaders[client_id],\nIndexError: list index out of range\n',)
[2024-06-25 12:38:15,675][flwr][ERROR] - Traceback (most recent call last):
  File "/Users/saisatyajonnalagadda/miniforge3/envs/carbFL/lib/python3.10/site-packages/flwr/simulation/ray_transport/ray_client_proxy.py", line 138, in _submit_job
    res = self.actor_pool.get_client_result(self.cid, timeout)
  File "/Users/saisatyajonnalagadda/miniforge3/envs/carbFL/lib/python3.10/site-packages/flwr/simulation/ray_transport/ray_actor.py", line 414, in get_client_result
    return self._fetch_future_result(cid)
  File "/Users/saisatyajonnalagadda/miniforge3/envs/carbFL/lib/python3.10/site-packages/flwr/simulation/ray_transport/ray_actor.py", line 300, in _fetch_future_result
    res_cid, res = ray.get(future)  # type: (str, ClientRes)
  File "/Users/saisatyajonnalagadda/miniforge3/envs/carbFL/lib/python3.10/site-packages/ray/_private/auto_init_hook.py", line 24, in auto_init_wrapper
    return fn(*args, **kwargs)
  File "/Users/saisatyajonnalagadda/miniforge3/envs/carbFL/lib/python3.10/site-packages/ray/_private/client_mode_hook.py", line 103, in wrapper
    return func(*args, **kwargs)
  File "/Users/saisatyajonnalagadda/miniforge3/envs/carbFL/lib/python3.10/site-packages/ray/_private/worker.py", line 2524, in get
    raise value.as_instanceof_cause()
ray.exceptions.RayTaskError: [36mray::DefaultActor.run()[39m (pid=92184, ip=127.0.0.1, actor_id=c5a177515e127fd68bae825401000000, repr=<flwr.simulation.ray_transport.ray_actor.DefaultActor object at 0x1060fe050>)
ray.exceptions.OutOfDiskError: Local disk is full
The object cannot be created because the local object store is full and the local disk's utilization is over capacity (95% by default).Tip: Use `df` on this node to check disk usage and `ray memory` to check object store memory usage.

[2024-06-25 12:38:15,677][flwr][ERROR] - Traceback (most recent call last):
  File "/Users/saisatyajonnalagadda/miniforge3/envs/carbFL/lib/python3.10/site-packages/flwr/simulation/ray_transport/ray_client_proxy.py", line 138, in _submit_job
    res = self.actor_pool.get_client_result(self.cid, timeout)
  File "/Users/saisatyajonnalagadda/miniforge3/envs/carbFL/lib/python3.10/site-packages/flwr/simulation/ray_transport/ray_actor.py", line 414, in get_client_result
    return self._fetch_future_result(cid)
  File "/Users/saisatyajonnalagadda/miniforge3/envs/carbFL/lib/python3.10/site-packages/flwr/simulation/ray_transport/ray_actor.py", line 300, in _fetch_future_result
    res_cid, res = ray.get(future)  # type: (str, ClientRes)
  File "/Users/saisatyajonnalagadda/miniforge3/envs/carbFL/lib/python3.10/site-packages/ray/_private/auto_init_hook.py", line 24, in auto_init_wrapper
    return fn(*args, **kwargs)
  File "/Users/saisatyajonnalagadda/miniforge3/envs/carbFL/lib/python3.10/site-packages/ray/_private/client_mode_hook.py", line 103, in wrapper
    return func(*args, **kwargs)
  File "/Users/saisatyajonnalagadda/miniforge3/envs/carbFL/lib/python3.10/site-packages/ray/_private/worker.py", line 2524, in get
    raise value.as_instanceof_cause()
ray.exceptions.RayTaskError(ClientException): [36mray::DefaultActor.run()[39m (pid=92184, ip=127.0.0.1, actor_id=c5a177515e127fd68bae825401000000, repr=<flwr.simulation.ray_transport.ray_actor.DefaultActor object at 0x1060fe050>)
  File "/Users/saisatyajonnalagadda/current_projects/carb_aware_model_adaption_FL/main2.py", line 116, in client_fn
    trainloader=trainloaders[client_id],
IndexError: list index out of range

The above exception was the direct cause of the following exception:

[36mray::DefaultActor.run()[39m (pid=92184, ip=127.0.0.1, actor_id=c5a177515e127fd68bae825401000000, repr=<flwr.simulation.ray_transport.ray_actor.DefaultActor object at 0x1060fe050>)
  File "/Users/saisatyajonnalagadda/miniforge3/envs/carbFL/lib/python3.10/site-packages/flwr/simulation/ray_transport/ray_actor.py", line 84, in run
    raise ClientException(str(message)) from ex
flwr.simulation.ray_transport.ray_actor.ClientException: 
>>>>>>>A ClientException occurred.('\n\tSomething went wrong when running your client workload.\n\tClient 84_Mexico City_small crashed when the DefaultActor was running its workload.\n\tException triggered on the client side: Traceback (most recent call last):\n  File "/Users/saisatyajonnalagadda/miniforge3/envs/carbFL/lib/python3.10/site-packages/flwr/simulation/ray_transport/ray_actor.py", line 70, in run\n    client = check_clientfn_returns_client(client_fn(cid))\n  File "/Users/saisatyajonnalagadda/current_projects/carb_aware_model_adaption_FL/main2.py", line 116, in client_fn\n    trainloader=trainloaders[client_id],\nIndexError: list index out of range\n',)

[2024-06-25 12:38:15,678][flwr][ERROR] - Traceback (most recent call last):
  File "/Users/saisatyajonnalagadda/miniforge3/envs/carbFL/lib/python3.10/site-packages/flwr/simulation/ray_transport/ray_client_proxy.py", line 138, in _submit_job
    res = self.actor_pool.get_client_result(self.cid, timeout)
  File "/Users/saisatyajonnalagadda/miniforge3/envs/carbFL/lib/python3.10/site-packages/flwr/simulation/ray_transport/ray_actor.py", line 414, in get_client_result
    return self._fetch_future_result(cid)
  File "/Users/saisatyajonnalagadda/miniforge3/envs/carbFL/lib/python3.10/site-packages/flwr/simulation/ray_transport/ray_actor.py", line 300, in _fetch_future_result
    res_cid, res = ray.get(future)  # type: (str, ClientRes)
  File "/Users/saisatyajonnalagadda/miniforge3/envs/carbFL/lib/python3.10/site-packages/ray/_private/auto_init_hook.py", line 24, in auto_init_wrapper
    return fn(*args, **kwargs)
  File "/Users/saisatyajonnalagadda/miniforge3/envs/carbFL/lib/python3.10/site-packages/ray/_private/client_mode_hook.py", line 103, in wrapper
    return func(*args, **kwargs)
  File "/Users/saisatyajonnalagadda/miniforge3/envs/carbFL/lib/python3.10/site-packages/ray/_private/worker.py", line 2524, in get
    raise value.as_instanceof_cause()
ray.exceptions.RayTaskError(ClientException): [36mray::DefaultActor.run()[39m (pid=92187, ip=127.0.0.1, actor_id=99ee256a1db7a48f08793abb01000000, repr=<flwr.simulation.ray_transport.ray_actor.DefaultActor object at 0x13049a050>)
  File "/Users/saisatyajonnalagadda/current_projects/carb_aware_model_adaption_FL/main2.py", line 116, in client_fn
    trainloader=trainloaders[client_id],
IndexError: list index out of range

The above exception was the direct cause of the following exception:

[36mray::DefaultActor.run()[39m (pid=92187, ip=127.0.0.1, actor_id=99ee256a1db7a48f08793abb01000000, repr=<flwr.simulation.ray_transport.ray_actor.DefaultActor object at 0x13049a050>)
  File "/Users/saisatyajonnalagadda/miniforge3/envs/carbFL/lib/python3.10/site-packages/flwr/simulation/ray_transport/ray_actor.py", line 84, in run
    raise ClientException(str(message)) from ex
flwr.simulation.ray_transport.ray_actor.ClientException: 
>>>>>>>A ClientException occurred.('\n\tSomething went wrong when running your client workload.\n\tClient 89_San Francisco_small crashed when the DefaultActor was running its workload.\n\tException triggered on the client side: Traceback (most recent call last):\n  File "/Users/saisatyajonnalagadda/miniforge3/envs/carbFL/lib/python3.10/site-packages/flwr/simulation/ray_transport/ray_actor.py", line 70, in run\n    client = check_clientfn_returns_client(client_fn(cid))\n  File "/Users/saisatyajonnalagadda/current_projects/carb_aware_model_adaption_FL/main2.py", line 116, in client_fn\n    trainloader=trainloaders[client_id],\nIndexError: list index out of range\n',)

[2024-06-25 12:38:15,683][flwr][ERROR] - [36mray::DefaultActor.run()[39m (pid=92184, ip=127.0.0.1, actor_id=c5a177515e127fd68bae825401000000, repr=<flwr.simulation.ray_transport.ray_actor.DefaultActor object at 0x1060fe050>)
ray.exceptions.OutOfDiskError: Local disk is full
The object cannot be created because the local object store is full and the local disk's utilization is over capacity (95% by default).Tip: Use `df` on this node to check disk usage and `ray memory` to check object store memory usage.
[2024-06-25 12:38:15,683][flwr][ERROR] - [36mray::DefaultActor.run()[39m (pid=92184, ip=127.0.0.1, actor_id=c5a177515e127fd68bae825401000000, repr=<flwr.simulation.ray_transport.ray_actor.DefaultActor object at 0x1060fe050>)
  File "/Users/saisatyajonnalagadda/current_projects/carb_aware_model_adaption_FL/main2.py", line 116, in client_fn
    trainloader=trainloaders[client_id],
IndexError: list index out of range

The above exception was the direct cause of the following exception:

[36mray::DefaultActor.run()[39m (pid=92184, ip=127.0.0.1, actor_id=c5a177515e127fd68bae825401000000, repr=<flwr.simulation.ray_transport.ray_actor.DefaultActor object at 0x1060fe050>)
  File "/Users/saisatyajonnalagadda/miniforge3/envs/carbFL/lib/python3.10/site-packages/flwr/simulation/ray_transport/ray_actor.py", line 84, in run
    raise ClientException(str(message)) from ex
flwr.simulation.ray_transport.ray_actor.ClientException: 
>>>>>>>A ClientException occurred.('\n\tSomething went wrong when running your client workload.\n\tClient 84_Mexico City_small crashed when the DefaultActor was running its workload.\n\tException triggered on the client side: Traceback (most recent call last):\n  File "/Users/saisatyajonnalagadda/miniforge3/envs/carbFL/lib/python3.10/site-packages/flwr/simulation/ray_transport/ray_actor.py", line 70, in run\n    client = check_clientfn_returns_client(client_fn(cid))\n  File "/Users/saisatyajonnalagadda/current_projects/carb_aware_model_adaption_FL/main2.py", line 116, in client_fn\n    trainloader=trainloaders[client_id],\nIndexError: list index out of range\n',)
[2024-06-25 12:38:15,683][flwr][ERROR] - [36mray::DefaultActor.run()[39m (pid=92187, ip=127.0.0.1, actor_id=99ee256a1db7a48f08793abb01000000, repr=<flwr.simulation.ray_transport.ray_actor.DefaultActor object at 0x13049a050>)
  File "/Users/saisatyajonnalagadda/current_projects/carb_aware_model_adaption_FL/main2.py", line 116, in client_fn
    trainloader=trainloaders[client_id],
IndexError: list index out of range

The above exception was the direct cause of the following exception:

[36mray::DefaultActor.run()[39m (pid=92187, ip=127.0.0.1, actor_id=99ee256a1db7a48f08793abb01000000, repr=<flwr.simulation.ray_transport.ray_actor.DefaultActor object at 0x13049a050>)
  File "/Users/saisatyajonnalagadda/miniforge3/envs/carbFL/lib/python3.10/site-packages/flwr/simulation/ray_transport/ray_actor.py", line 84, in run
    raise ClientException(str(message)) from ex
flwr.simulation.ray_transport.ray_actor.ClientException: 
>>>>>>>A ClientException occurred.('\n\tSomething went wrong when running your client workload.\n\tClient 89_San Francisco_small crashed when the DefaultActor was running its workload.\n\tException triggered on the client side: Traceback (most recent call last):\n  File "/Users/saisatyajonnalagadda/miniforge3/envs/carbFL/lib/python3.10/site-packages/flwr/simulation/ray_transport/ray_actor.py", line 70, in run\n    client = check_clientfn_returns_client(client_fn(cid))\n  File "/Users/saisatyajonnalagadda/current_projects/carb_aware_model_adaption_FL/main2.py", line 116, in client_fn\n    trainloader=trainloaders[client_id],\nIndexError: list index out of range\n',)
[2024-06-25 12:38:16,107][flwr][ERROR] - Traceback (most recent call last):
  File "/Users/saisatyajonnalagadda/miniforge3/envs/carbFL/lib/python3.10/site-packages/flwr/simulation/ray_transport/ray_client_proxy.py", line 138, in _submit_job
    res = self.actor_pool.get_client_result(self.cid, timeout)
  File "/Users/saisatyajonnalagadda/miniforge3/envs/carbFL/lib/python3.10/site-packages/flwr/simulation/ray_transport/ray_actor.py", line 414, in get_client_result
    return self._fetch_future_result(cid)
  File "/Users/saisatyajonnalagadda/miniforge3/envs/carbFL/lib/python3.10/site-packages/flwr/simulation/ray_transport/ray_actor.py", line 300, in _fetch_future_result
    res_cid, res = ray.get(future)  # type: (str, ClientRes)
  File "/Users/saisatyajonnalagadda/miniforge3/envs/carbFL/lib/python3.10/site-packages/ray/_private/auto_init_hook.py", line 24, in auto_init_wrapper
    return fn(*args, **kwargs)
  File "/Users/saisatyajonnalagadda/miniforge3/envs/carbFL/lib/python3.10/site-packages/ray/_private/client_mode_hook.py", line 103, in wrapper
    return func(*args, **kwargs)
  File "/Users/saisatyajonnalagadda/miniforge3/envs/carbFL/lib/python3.10/site-packages/ray/_private/worker.py", line 2524, in get
    raise value.as_instanceof_cause()
ray.exceptions.RayTaskError(ClientException): [36mray::DefaultActor.run()[39m (pid=92186, ip=127.0.0.1, actor_id=525e3b614591d530a221d69b01000000, repr=<flwr.simulation.ray_transport.ray_actor.DefaultActor object at 0x10ab81fc0>)
  File "/Users/saisatyajonnalagadda/current_projects/carb_aware_model_adaption_FL/main2.py", line 116, in client_fn
    trainloader=trainloaders[client_id],
IndexError: list index out of range

The above exception was the direct cause of the following exception:

[36mray::DefaultActor.run()[39m (pid=92186, ip=127.0.0.1, actor_id=525e3b614591d530a221d69b01000000, repr=<flwr.simulation.ray_transport.ray_actor.DefaultActor object at 0x10ab81fc0>)
  File "/Users/saisatyajonnalagadda/miniforge3/envs/carbFL/lib/python3.10/site-packages/flwr/simulation/ray_transport/ray_actor.py", line 84, in run
    raise ClientException(str(message)) from ex
flwr.simulation.ray_transport.ray_actor.ClientException: 
>>>>>>>A ClientException occurred.('\n\tSomething went wrong when running your client workload.\n\tClient 90_San Francisco_small crashed when the DefaultActor was running its workload.\n\tException triggered on the client side: Traceback (most recent call last):\n  File "/Users/saisatyajonnalagadda/miniforge3/envs/carbFL/lib/python3.10/site-packages/flwr/simulation/ray_transport/ray_actor.py", line 70, in run\n    client = check_clientfn_returns_client(client_fn(cid))\n  File "/Users/saisatyajonnalagadda/current_projects/carb_aware_model_adaption_FL/main2.py", line 116, in client_fn\n    trainloader=trainloaders[client_id],\nIndexError: list index out of range\n',)

[2024-06-25 12:38:16,107][flwr][ERROR] - Traceback (most recent call last):
  File "/Users/saisatyajonnalagadda/miniforge3/envs/carbFL/lib/python3.10/site-packages/flwr/simulation/ray_transport/ray_client_proxy.py", line 138, in _submit_job
    res = self.actor_pool.get_client_result(self.cid, timeout)
  File "/Users/saisatyajonnalagadda/miniforge3/envs/carbFL/lib/python3.10/site-packages/flwr/simulation/ray_transport/ray_actor.py", line 414, in get_client_result
    return self._fetch_future_result(cid)
  File "/Users/saisatyajonnalagadda/miniforge3/envs/carbFL/lib/python3.10/site-packages/flwr/simulation/ray_transport/ray_actor.py", line 300, in _fetch_future_result
    res_cid, res = ray.get(future)  # type: (str, ClientRes)
  File "/Users/saisatyajonnalagadda/miniforge3/envs/carbFL/lib/python3.10/site-packages/ray/_private/auto_init_hook.py", line 24, in auto_init_wrapper
    return fn(*args, **kwargs)
  File "/Users/saisatyajonnalagadda/miniforge3/envs/carbFL/lib/python3.10/site-packages/ray/_private/client_mode_hook.py", line 103, in wrapper
    return func(*args, **kwargs)
  File "/Users/saisatyajonnalagadda/miniforge3/envs/carbFL/lib/python3.10/site-packages/ray/_private/worker.py", line 2524, in get
    raise value.as_instanceof_cause()
ray.exceptions.RayTaskError(ClientException): [36mray::DefaultActor.run()[39m (pid=92185, ip=127.0.0.1, actor_id=ea0b5fe9d3b380ac6560964a01000000, repr=<flwr.simulation.ray_transport.ray_actor.DefaultActor object at 0x111e0e050>)
  File "/Users/saisatyajonnalagadda/current_projects/carb_aware_model_adaption_FL/main2.py", line 116, in client_fn
    trainloader=trainloaders[client_id],
IndexError: list index out of range

The above exception was the direct cause of the following exception:

[36mray::DefaultActor.run()[39m (pid=92185, ip=127.0.0.1, actor_id=ea0b5fe9d3b380ac6560964a01000000, repr=<flwr.simulation.ray_transport.ray_actor.DefaultActor object at 0x111e0e050>)
  File "/Users/saisatyajonnalagadda/miniforge3/envs/carbFL/lib/python3.10/site-packages/flwr/simulation/ray_transport/ray_actor.py", line 84, in run
    raise ClientException(str(message)) from ex
flwr.simulation.ray_transport.ray_actor.ClientException: 
>>>>>>>A ClientException occurred.('\n\tSomething went wrong when running your client workload.\n\tClient 92_San Francisco_mid crashed when the DefaultActor was running its workload.\n\tException triggered on the client side: Traceback (most recent call last):\n  File "/Users/saisatyajonnalagadda/miniforge3/envs/carbFL/lib/python3.10/site-packages/flwr/simulation/ray_transport/ray_actor.py", line 70, in run\n    client = check_clientfn_returns_client(client_fn(cid))\n  File "/Users/saisatyajonnalagadda/current_projects/carb_aware_model_adaption_FL/main2.py", line 116, in client_fn\n    trainloader=trainloaders[client_id],\nIndexError: list index out of range\n',)

[2024-06-25 12:38:16,107][flwr][ERROR] - Traceback (most recent call last):
  File "/Users/saisatyajonnalagadda/miniforge3/envs/carbFL/lib/python3.10/site-packages/flwr/simulation/ray_transport/ray_client_proxy.py", line 138, in _submit_job
    res = self.actor_pool.get_client_result(self.cid, timeout)
  File "/Users/saisatyajonnalagadda/miniforge3/envs/carbFL/lib/python3.10/site-packages/flwr/simulation/ray_transport/ray_actor.py", line 414, in get_client_result
    return self._fetch_future_result(cid)
  File "/Users/saisatyajonnalagadda/miniforge3/envs/carbFL/lib/python3.10/site-packages/flwr/simulation/ray_transport/ray_actor.py", line 300, in _fetch_future_result
    res_cid, res = ray.get(future)  # type: (str, ClientRes)
  File "/Users/saisatyajonnalagadda/miniforge3/envs/carbFL/lib/python3.10/site-packages/ray/_private/auto_init_hook.py", line 24, in auto_init_wrapper
    return fn(*args, **kwargs)
  File "/Users/saisatyajonnalagadda/miniforge3/envs/carbFL/lib/python3.10/site-packages/ray/_private/client_mode_hook.py", line 103, in wrapper
    return func(*args, **kwargs)
  File "/Users/saisatyajonnalagadda/miniforge3/envs/carbFL/lib/python3.10/site-packages/ray/_private/worker.py", line 2513, in get
    raise ValueError(
ValueError: 'object_refs' must either be an ObjectRef or a list of ObjectRefs.

[2024-06-25 12:38:16,107][flwr][ERROR] - Traceback (most recent call last):
  File "/Users/saisatyajonnalagadda/miniforge3/envs/carbFL/lib/python3.10/site-packages/flwr/simulation/ray_transport/ray_client_proxy.py", line 138, in _submit_job
    res = self.actor_pool.get_client_result(self.cid, timeout)
  File "/Users/saisatyajonnalagadda/miniforge3/envs/carbFL/lib/python3.10/site-packages/flwr/simulation/ray_transport/ray_actor.py", line 414, in get_client_result
    return self._fetch_future_result(cid)
  File "/Users/saisatyajonnalagadda/miniforge3/envs/carbFL/lib/python3.10/site-packages/flwr/simulation/ray_transport/ray_actor.py", line 300, in _fetch_future_result
    res_cid, res = ray.get(future)  # type: (str, ClientRes)
  File "/Users/saisatyajonnalagadda/miniforge3/envs/carbFL/lib/python3.10/site-packages/ray/_private/auto_init_hook.py", line 24, in auto_init_wrapper
    return fn(*args, **kwargs)
  File "/Users/saisatyajonnalagadda/miniforge3/envs/carbFL/lib/python3.10/site-packages/ray/_private/client_mode_hook.py", line 103, in wrapper
    return func(*args, **kwargs)
  File "/Users/saisatyajonnalagadda/miniforge3/envs/carbFL/lib/python3.10/site-packages/ray/_private/worker.py", line 2513, in get
    raise ValueError(
ValueError: 'object_refs' must either be an ObjectRef or a list of ObjectRefs.

[2024-06-25 12:38:16,108][flwr][ERROR] - [36mray::DefaultActor.run()[39m (pid=92186, ip=127.0.0.1, actor_id=525e3b614591d530a221d69b01000000, repr=<flwr.simulation.ray_transport.ray_actor.DefaultActor object at 0x10ab81fc0>)
  File "/Users/saisatyajonnalagadda/current_projects/carb_aware_model_adaption_FL/main2.py", line 116, in client_fn
    trainloader=trainloaders[client_id],
IndexError: list index out of range

The above exception was the direct cause of the following exception:

[36mray::DefaultActor.run()[39m (pid=92186, ip=127.0.0.1, actor_id=525e3b614591d530a221d69b01000000, repr=<flwr.simulation.ray_transport.ray_actor.DefaultActor object at 0x10ab81fc0>)
  File "/Users/saisatyajonnalagadda/miniforge3/envs/carbFL/lib/python3.10/site-packages/flwr/simulation/ray_transport/ray_actor.py", line 84, in run
    raise ClientException(str(message)) from ex
flwr.simulation.ray_transport.ray_actor.ClientException: 
>>>>>>>A ClientException occurred.('\n\tSomething went wrong when running your client workload.\n\tClient 90_San Francisco_small crashed when the DefaultActor was running its workload.\n\tException triggered on the client side: Traceback (most recent call last):\n  File "/Users/saisatyajonnalagadda/miniforge3/envs/carbFL/lib/python3.10/site-packages/flwr/simulation/ray_transport/ray_actor.py", line 70, in run\n    client = check_clientfn_returns_client(client_fn(cid))\n  File "/Users/saisatyajonnalagadda/current_projects/carb_aware_model_adaption_FL/main2.py", line 116, in client_fn\n    trainloader=trainloaders[client_id],\nIndexError: list index out of range\n',)
[2024-06-25 12:38:16,108][flwr][ERROR] - [36mray::DefaultActor.run()[39m (pid=92185, ip=127.0.0.1, actor_id=ea0b5fe9d3b380ac6560964a01000000, repr=<flwr.simulation.ray_transport.ray_actor.DefaultActor object at 0x111e0e050>)
  File "/Users/saisatyajonnalagadda/current_projects/carb_aware_model_adaption_FL/main2.py", line 116, in client_fn
    trainloader=trainloaders[client_id],
IndexError: list index out of range

The above exception was the direct cause of the following exception:

[36mray::DefaultActor.run()[39m (pid=92185, ip=127.0.0.1, actor_id=ea0b5fe9d3b380ac6560964a01000000, repr=<flwr.simulation.ray_transport.ray_actor.DefaultActor object at 0x111e0e050>)
  File "/Users/saisatyajonnalagadda/miniforge3/envs/carbFL/lib/python3.10/site-packages/flwr/simulation/ray_transport/ray_actor.py", line 84, in run
    raise ClientException(str(message)) from ex
flwr.simulation.ray_transport.ray_actor.ClientException: 
>>>>>>>A ClientException occurred.('\n\tSomething went wrong when running your client workload.\n\tClient 92_San Francisco_mid crashed when the DefaultActor was running its workload.\n\tException triggered on the client side: Traceback (most recent call last):\n  File "/Users/saisatyajonnalagadda/miniforge3/envs/carbFL/lib/python3.10/site-packages/flwr/simulation/ray_transport/ray_actor.py", line 70, in run\n    client = check_clientfn_returns_client(client_fn(cid))\n  File "/Users/saisatyajonnalagadda/current_projects/carb_aware_model_adaption_FL/main2.py", line 116, in client_fn\n    trainloader=trainloaders[client_id],\nIndexError: list index out of range\n',)
[2024-06-25 12:38:16,108][flwr][ERROR] - 'object_refs' must either be an ObjectRef or a list of ObjectRefs.
[2024-06-25 12:38:16,108][flwr][ERROR] - 'object_refs' must either be an ObjectRef or a list of ObjectRefs.
