[2024-06-25 12:46:40,387][flwr][INFO] - Starting Flower simulation, config: ServerConfig(num_rounds=1, round_timeout=None)
[2024-06-25 12:46:42,669][flwr][INFO] - Flower VCE: Ray initialized with resources: {'memory': 2585985024.0, 'CPU': 8.0, 'node:127.0.0.1': 1.0, 'node:__internal_head__': 1.0, 'object_store_memory': 1292992512.0}
[2024-06-25 12:46:42,669][flwr][INFO] - Optimize your simulation with Flower VCE: https://flower.dev/docs/framework/how-to-run-simulations.html
[2024-06-25 12:46:42,670][flwr][INFO] - Flower VCE: Resources for each Virtual Client: {'num_cpus': 1.0, 'num_gpus': 0}
[2024-06-25 12:46:42,677][flwr][INFO] - Flower VCE: Creating VirtualClientEngineActorPool with 8 actors
[2024-06-25 12:46:42,677][flwr][INFO] - Initializing global parameters
[2024-06-25 12:46:42,677][flwr][INFO] - Using initial parameters provided by strategy
[2024-06-25 12:46:42,677][flwr][INFO] - Evaluating initial parameters
[2024-06-25 12:46:55,948][flwr][INFO] - initial parameters (loss, other metrics): 0.2418656432390213, {'accuracy': 0.1085}
[2024-06-25 12:46:55,948][flwr][INFO] - FL starting
[2024-06-25 12:46:55,996][flwr][DEBUG] - fit_round 1: strategy sampled 35 clients (out of 100)
[2024-06-25 12:47:42,478][flwr][ERROR] - Traceback (most recent call last):
  File "/Users/saisatyajonnalagadda/miniforge3/envs/carbFL/lib/python3.10/site-packages/flwr/simulation/ray_transport/ray_client_proxy.py", line 138, in _submit_job
    res = self.actor_pool.get_client_result(self.cid, timeout)
  File "/Users/saisatyajonnalagadda/miniforge3/envs/carbFL/lib/python3.10/site-packages/flwr/simulation/ray_transport/ray_actor.py", line 414, in get_client_result
    return self._fetch_future_result(cid)
  File "/Users/saisatyajonnalagadda/miniforge3/envs/carbFL/lib/python3.10/site-packages/flwr/simulation/ray_transport/ray_actor.py", line 300, in _fetch_future_result
    res_cid, res = ray.get(future)  # type: (str, ClientRes)
  File "/Users/saisatyajonnalagadda/miniforge3/envs/carbFL/lib/python3.10/site-packages/ray/_private/auto_init_hook.py", line 24, in auto_init_wrapper
    return fn(*args, **kwargs)
  File "/Users/saisatyajonnalagadda/miniforge3/envs/carbFL/lib/python3.10/site-packages/ray/_private/client_mode_hook.py", line 103, in wrapper
    return func(*args, **kwargs)
  File "/Users/saisatyajonnalagadda/miniforge3/envs/carbFL/lib/python3.10/site-packages/ray/_private/worker.py", line 2524, in get
    raise value.as_instanceof_cause()
ray.exceptions.RayTaskError(ClientException): [36mray::DefaultActor.run()[39m (pid=93383, ip=127.0.0.1, actor_id=d178135f2067fdfeebe7c64c01000000, repr=<flwr.simulation.ray_transport.ray_actor.DefaultActor object at 0x10730e080>)
  File "/Users/saisatyajonnalagadda/current_projects/carb_aware_model_adaption_FL/main2.py", line 116, in client_fn
    trainloader=trainloaders[client_id],
IndexError: list index out of range

The above exception was the direct cause of the following exception:

[36mray::DefaultActor.run()[39m (pid=93383, ip=127.0.0.1, actor_id=d178135f2067fdfeebe7c64c01000000, repr=<flwr.simulation.ray_transport.ray_actor.DefaultActor object at 0x10730e080>)
  File "/Users/saisatyajonnalagadda/miniforge3/envs/carbFL/lib/python3.10/site-packages/flwr/simulation/ray_transport/ray_actor.py", line 84, in run
    raise ClientException(str(message)) from ex
flwr.simulation.ray_transport.ray_actor.ClientException: 
>>>>>>>A ClientException occurred.('\n\tSomething went wrong when running your client workload.\n\tClient 53_Sydney_large crashed when the DefaultActor was running its workload.\n\tException triggered on the client side: Traceback (most recent call last):\n  File "/Users/saisatyajonnalagadda/miniforge3/envs/carbFL/lib/python3.10/site-packages/flwr/simulation/ray_transport/ray_actor.py", line 70, in run\n    client = check_clientfn_returns_client(client_fn(cid))\n  File "/Users/saisatyajonnalagadda/current_projects/carb_aware_model_adaption_FL/main2.py", line 116, in client_fn\n    trainloader=trainloaders[client_id],\nIndexError: list index out of range\n',)

[2024-06-25 12:47:42,594][flwr][ERROR] - [36mray::DefaultActor.run()[39m (pid=93383, ip=127.0.0.1, actor_id=d178135f2067fdfeebe7c64c01000000, repr=<flwr.simulation.ray_transport.ray_actor.DefaultActor object at 0x10730e080>)
  File "/Users/saisatyajonnalagadda/current_projects/carb_aware_model_adaption_FL/main2.py", line 116, in client_fn
    trainloader=trainloaders[client_id],
IndexError: list index out of range

The above exception was the direct cause of the following exception:

[36mray::DefaultActor.run()[39m (pid=93383, ip=127.0.0.1, actor_id=d178135f2067fdfeebe7c64c01000000, repr=<flwr.simulation.ray_transport.ray_actor.DefaultActor object at 0x10730e080>)
  File "/Users/saisatyajonnalagadda/miniforge3/envs/carbFL/lib/python3.10/site-packages/flwr/simulation/ray_transport/ray_actor.py", line 84, in run
    raise ClientException(str(message)) from ex
flwr.simulation.ray_transport.ray_actor.ClientException: 
>>>>>>>A ClientException occurred.('\n\tSomething went wrong when running your client workload.\n\tClient 53_Sydney_large crashed when the DefaultActor was running its workload.\n\tException triggered on the client side: Traceback (most recent call last):\n  File "/Users/saisatyajonnalagadda/miniforge3/envs/carbFL/lib/python3.10/site-packages/flwr/simulation/ray_transport/ray_actor.py", line 70, in run\n    client = check_clientfn_returns_client(client_fn(cid))\n  File "/Users/saisatyajonnalagadda/current_projects/carb_aware_model_adaption_FL/main2.py", line 116, in client_fn\n    trainloader=trainloaders[client_id],\nIndexError: list index out of range\n',)
[2024-06-25 12:47:55,192][flwr][ERROR] - Traceback (most recent call last):
  File "/Users/saisatyajonnalagadda/miniforge3/envs/carbFL/lib/python3.10/site-packages/flwr/simulation/ray_transport/ray_client_proxy.py", line 138, in _submit_job
    res = self.actor_pool.get_client_result(self.cid, timeout)
  File "/Users/saisatyajonnalagadda/miniforge3/envs/carbFL/lib/python3.10/site-packages/flwr/simulation/ray_transport/ray_actor.py", line 414, in get_client_result
    return self._fetch_future_result(cid)
  File "/Users/saisatyajonnalagadda/miniforge3/envs/carbFL/lib/python3.10/site-packages/flwr/simulation/ray_transport/ray_actor.py", line 300, in _fetch_future_result
    res_cid, res = ray.get(future)  # type: (str, ClientRes)
  File "/Users/saisatyajonnalagadda/miniforge3/envs/carbFL/lib/python3.10/site-packages/ray/_private/auto_init_hook.py", line 24, in auto_init_wrapper
    return fn(*args, **kwargs)
  File "/Users/saisatyajonnalagadda/miniforge3/envs/carbFL/lib/python3.10/site-packages/ray/_private/client_mode_hook.py", line 103, in wrapper
    return func(*args, **kwargs)
  File "/Users/saisatyajonnalagadda/miniforge3/envs/carbFL/lib/python3.10/site-packages/ray/_private/worker.py", line 2524, in get
    raise value.as_instanceof_cause()
ray.exceptions.RayTaskError(ClientException): [36mray::DefaultActor.run()[39m (pid=93383, ip=127.0.0.1, actor_id=d178135f2067fdfeebe7c64c01000000, repr=<flwr.simulation.ray_transport.ray_actor.DefaultActor object at 0x10730e080>)
  File "/Users/saisatyajonnalagadda/current_projects/carb_aware_model_adaption_FL/main2.py", line 116, in client_fn
    trainloader=trainloaders[client_id],
IndexError: list index out of range

The above exception was the direct cause of the following exception:

[36mray::DefaultActor.run()[39m (pid=93383, ip=127.0.0.1, actor_id=d178135f2067fdfeebe7c64c01000000, repr=<flwr.simulation.ray_transport.ray_actor.DefaultActor object at 0x10730e080>)
  File "/Users/saisatyajonnalagadda/miniforge3/envs/carbFL/lib/python3.10/site-packages/flwr/simulation/ray_transport/ray_actor.py", line 84, in run
    raise ClientException(str(message)) from ex
flwr.simulation.ray_transport.ray_actor.ClientException: 
>>>>>>>A ClientException occurred.('\n\tSomething went wrong when running your client workload.\n\tClient 55_Hong Kong_large crashed when the DefaultActor was running its workload.\n\tException triggered on the client side: Traceback (most recent call last):\n  File "/Users/saisatyajonnalagadda/miniforge3/envs/carbFL/lib/python3.10/site-packages/flwr/simulation/ray_transport/ray_actor.py", line 70, in run\n    client = check_clientfn_returns_client(client_fn(cid))\n  File "/Users/saisatyajonnalagadda/current_projects/carb_aware_model_adaption_FL/main2.py", line 116, in client_fn\n    trainloader=trainloaders[client_id],\nIndexError: list index out of range\n',)

[2024-06-25 12:47:55,241][flwr][ERROR] - [36mray::DefaultActor.run()[39m (pid=93383, ip=127.0.0.1, actor_id=d178135f2067fdfeebe7c64c01000000, repr=<flwr.simulation.ray_transport.ray_actor.DefaultActor object at 0x10730e080>)
  File "/Users/saisatyajonnalagadda/current_projects/carb_aware_model_adaption_FL/main2.py", line 116, in client_fn
    trainloader=trainloaders[client_id],
IndexError: list index out of range

The above exception was the direct cause of the following exception:

[36mray::DefaultActor.run()[39m (pid=93383, ip=127.0.0.1, actor_id=d178135f2067fdfeebe7c64c01000000, repr=<flwr.simulation.ray_transport.ray_actor.DefaultActor object at 0x10730e080>)
  File "/Users/saisatyajonnalagadda/miniforge3/envs/carbFL/lib/python3.10/site-packages/flwr/simulation/ray_transport/ray_actor.py", line 84, in run
    raise ClientException(str(message)) from ex
flwr.simulation.ray_transport.ray_actor.ClientException: 
>>>>>>>A ClientException occurred.('\n\tSomething went wrong when running your client workload.\n\tClient 55_Hong Kong_large crashed when the DefaultActor was running its workload.\n\tException triggered on the client side: Traceback (most recent call last):\n  File "/Users/saisatyajonnalagadda/miniforge3/envs/carbFL/lib/python3.10/site-packages/flwr/simulation/ray_transport/ray_actor.py", line 70, in run\n    client = check_clientfn_returns_client(client_fn(cid))\n  File "/Users/saisatyajonnalagadda/current_projects/carb_aware_model_adaption_FL/main2.py", line 116, in client_fn\n    trainloader=trainloaders[client_id],\nIndexError: list index out of range\n',)
[2024-06-25 12:48:22,701][flwr][ERROR] - Traceback (most recent call last):
  File "/Users/saisatyajonnalagadda/miniforge3/envs/carbFL/lib/python3.10/site-packages/flwr/simulation/ray_transport/ray_client_proxy.py", line 138, in _submit_job
    res = self.actor_pool.get_client_result(self.cid, timeout)
  File "/Users/saisatyajonnalagadda/miniforge3/envs/carbFL/lib/python3.10/site-packages/flwr/simulation/ray_transport/ray_actor.py", line 414, in get_client_result
    return self._fetch_future_result(cid)
  File "/Users/saisatyajonnalagadda/miniforge3/envs/carbFL/lib/python3.10/site-packages/flwr/simulation/ray_transport/ray_actor.py", line 300, in _fetch_future_result
    res_cid, res = ray.get(future)  # type: (str, ClientRes)
  File "/Users/saisatyajonnalagadda/miniforge3/envs/carbFL/lib/python3.10/site-packages/ray/_private/auto_init_hook.py", line 24, in auto_init_wrapper
    return fn(*args, **kwargs)
  File "/Users/saisatyajonnalagadda/miniforge3/envs/carbFL/lib/python3.10/site-packages/ray/_private/client_mode_hook.py", line 103, in wrapper
    return func(*args, **kwargs)
  File "/Users/saisatyajonnalagadda/miniforge3/envs/carbFL/lib/python3.10/site-packages/ray/_private/worker.py", line 2524, in get
    raise value.as_instanceof_cause()
ray.exceptions.RayTaskError(ClientException): [36mray::DefaultActor.run()[39m (pid=93388, ip=127.0.0.1, actor_id=6e718db234739d23338590d901000000, repr=<flwr.simulation.ray_transport.ray_actor.DefaultActor object at 0x11220e020>)
  File "/Users/saisatyajonnalagadda/current_projects/carb_aware_model_adaption_FL/main2.py", line 116, in client_fn
    trainloader=trainloaders[client_id],
IndexError: list index out of range

The above exception was the direct cause of the following exception:

[36mray::DefaultActor.run()[39m (pid=93388, ip=127.0.0.1, actor_id=6e718db234739d23338590d901000000, repr=<flwr.simulation.ray_transport.ray_actor.DefaultActor object at 0x11220e020>)
  File "/Users/saisatyajonnalagadda/miniforge3/envs/carbFL/lib/python3.10/site-packages/flwr/simulation/ray_transport/ray_actor.py", line 84, in run
    raise ClientException(str(message)) from ex
flwr.simulation.ray_transport.ray_actor.ClientException: 
>>>>>>>A ClientException occurred.('\n\tSomething went wrong when running your client workload.\n\tClient 76_Sydney_large crashed when the DefaultActor was running its workload.\n\tException triggered on the client side: Traceback (most recent call last):\n  File "/Users/saisatyajonnalagadda/miniforge3/envs/carbFL/lib/python3.10/site-packages/flwr/simulation/ray_transport/ray_actor.py", line 70, in run\n    client = check_clientfn_returns_client(client_fn(cid))\n  File "/Users/saisatyajonnalagadda/current_projects/carb_aware_model_adaption_FL/main2.py", line 116, in client_fn\n    trainloader=trainloaders[client_id],\nIndexError: list index out of range\n',)

[2024-06-25 12:48:22,725][flwr][ERROR] - [36mray::DefaultActor.run()[39m (pid=93388, ip=127.0.0.1, actor_id=6e718db234739d23338590d901000000, repr=<flwr.simulation.ray_transport.ray_actor.DefaultActor object at 0x11220e020>)
  File "/Users/saisatyajonnalagadda/current_projects/carb_aware_model_adaption_FL/main2.py", line 116, in client_fn
    trainloader=trainloaders[client_id],
IndexError: list index out of range

The above exception was the direct cause of the following exception:

[36mray::DefaultActor.run()[39m (pid=93388, ip=127.0.0.1, actor_id=6e718db234739d23338590d901000000, repr=<flwr.simulation.ray_transport.ray_actor.DefaultActor object at 0x11220e020>)
  File "/Users/saisatyajonnalagadda/miniforge3/envs/carbFL/lib/python3.10/site-packages/flwr/simulation/ray_transport/ray_actor.py", line 84, in run
    raise ClientException(str(message)) from ex
flwr.simulation.ray_transport.ray_actor.ClientException: 
>>>>>>>A ClientException occurred.('\n\tSomething went wrong when running your client workload.\n\tClient 76_Sydney_large crashed when the DefaultActor was running its workload.\n\tException triggered on the client side: Traceback (most recent call last):\n  File "/Users/saisatyajonnalagadda/miniforge3/envs/carbFL/lib/python3.10/site-packages/flwr/simulation/ray_transport/ray_actor.py", line 70, in run\n    client = check_clientfn_returns_client(client_fn(cid))\n  File "/Users/saisatyajonnalagadda/current_projects/carb_aware_model_adaption_FL/main2.py", line 116, in client_fn\n    trainloader=trainloaders[client_id],\nIndexError: list index out of range\n',)
[2024-06-25 12:48:26,633][flwr][ERROR] - Traceback (most recent call last):
  File "/Users/saisatyajonnalagadda/miniforge3/envs/carbFL/lib/python3.10/site-packages/flwr/simulation/ray_transport/ray_client_proxy.py", line 138, in _submit_job
    res = self.actor_pool.get_client_result(self.cid, timeout)
  File "/Users/saisatyajonnalagadda/miniforge3/envs/carbFL/lib/python3.10/site-packages/flwr/simulation/ray_transport/ray_actor.py", line 414, in get_client_result
    return self._fetch_future_result(cid)
  File "/Users/saisatyajonnalagadda/miniforge3/envs/carbFL/lib/python3.10/site-packages/flwr/simulation/ray_transport/ray_actor.py", line 300, in _fetch_future_result
    res_cid, res = ray.get(future)  # type: (str, ClientRes)
  File "/Users/saisatyajonnalagadda/miniforge3/envs/carbFL/lib/python3.10/site-packages/ray/_private/auto_init_hook.py", line 24, in auto_init_wrapper
    return fn(*args, **kwargs)
  File "/Users/saisatyajonnalagadda/miniforge3/envs/carbFL/lib/python3.10/site-packages/ray/_private/client_mode_hook.py", line 103, in wrapper
    return func(*args, **kwargs)
  File "/Users/saisatyajonnalagadda/miniforge3/envs/carbFL/lib/python3.10/site-packages/ray/_private/worker.py", line 2524, in get
    raise value.as_instanceof_cause()
ray.exceptions.RayTaskError(ClientException): [36mray::DefaultActor.run()[39m (pid=93383, ip=127.0.0.1, actor_id=d178135f2067fdfeebe7c64c01000000, repr=<flwr.simulation.ray_transport.ray_actor.DefaultActor object at 0x10730e080>)
  File "/Users/saisatyajonnalagadda/current_projects/carb_aware_model_adaption_FL/main2.py", line 116, in client_fn
    trainloader=trainloaders[client_id],
IndexError: list index out of range

The above exception was the direct cause of the following exception:

[36mray::DefaultActor.run()[39m (pid=93383, ip=127.0.0.1, actor_id=d178135f2067fdfeebe7c64c01000000, repr=<flwr.simulation.ray_transport.ray_actor.DefaultActor object at 0x10730e080>)
  File "/Users/saisatyajonnalagadda/miniforge3/envs/carbFL/lib/python3.10/site-packages/flwr/simulation/ray_transport/ray_actor.py", line 84, in run
    raise ClientException(str(message)) from ex
flwr.simulation.ray_transport.ray_actor.ClientException: 
>>>>>>>A ClientException occurred.('\n\tSomething went wrong when running your client workload.\n\tClient 74_Hong Kong_large crashed when the DefaultActor was running its workload.\n\tException triggered on the client side: Traceback (most recent call last):\n  File "/Users/saisatyajonnalagadda/miniforge3/envs/carbFL/lib/python3.10/site-packages/flwr/simulation/ray_transport/ray_actor.py", line 70, in run\n    client = check_clientfn_returns_client(client_fn(cid))\n  File "/Users/saisatyajonnalagadda/current_projects/carb_aware_model_adaption_FL/main2.py", line 116, in client_fn\n    trainloader=trainloaders[client_id],\nIndexError: list index out of range\n',)

[2024-06-25 12:48:26,642][flwr][ERROR] - [36mray::DefaultActor.run()[39m (pid=93383, ip=127.0.0.1, actor_id=d178135f2067fdfeebe7c64c01000000, repr=<flwr.simulation.ray_transport.ray_actor.DefaultActor object at 0x10730e080>)
  File "/Users/saisatyajonnalagadda/current_projects/carb_aware_model_adaption_FL/main2.py", line 116, in client_fn
    trainloader=trainloaders[client_id],
IndexError: list index out of range

The above exception was the direct cause of the following exception:

[36mray::DefaultActor.run()[39m (pid=93383, ip=127.0.0.1, actor_id=d178135f2067fdfeebe7c64c01000000, repr=<flwr.simulation.ray_transport.ray_actor.DefaultActor object at 0x10730e080>)
  File "/Users/saisatyajonnalagadda/miniforge3/envs/carbFL/lib/python3.10/site-packages/flwr/simulation/ray_transport/ray_actor.py", line 84, in run
    raise ClientException(str(message)) from ex
flwr.simulation.ray_transport.ray_actor.ClientException: 
>>>>>>>A ClientException occurred.('\n\tSomething went wrong when running your client workload.\n\tClient 74_Hong Kong_large crashed when the DefaultActor was running its workload.\n\tException triggered on the client side: Traceback (most recent call last):\n  File "/Users/saisatyajonnalagadda/miniforge3/envs/carbFL/lib/python3.10/site-packages/flwr/simulation/ray_transport/ray_actor.py", line 70, in run\n    client = check_clientfn_returns_client(client_fn(cid))\n  File "/Users/saisatyajonnalagadda/current_projects/carb_aware_model_adaption_FL/main2.py", line 116, in client_fn\n    trainloader=trainloaders[client_id],\nIndexError: list index out of range\n',)
[2024-06-25 12:48:37,010][flwr][ERROR] - Traceback (most recent call last):
  File "/Users/saisatyajonnalagadda/miniforge3/envs/carbFL/lib/python3.10/site-packages/flwr/simulation/ray_transport/ray_client_proxy.py", line 138, in _submit_job
    res = self.actor_pool.get_client_result(self.cid, timeout)
  File "/Users/saisatyajonnalagadda/miniforge3/envs/carbFL/lib/python3.10/site-packages/flwr/simulation/ray_transport/ray_actor.py", line 414, in get_client_result
    return self._fetch_future_result(cid)
  File "/Users/saisatyajonnalagadda/miniforge3/envs/carbFL/lib/python3.10/site-packages/flwr/simulation/ray_transport/ray_actor.py", line 300, in _fetch_future_result
    res_cid, res = ray.get(future)  # type: (str, ClientRes)
  File "/Users/saisatyajonnalagadda/miniforge3/envs/carbFL/lib/python3.10/site-packages/ray/_private/auto_init_hook.py", line 24, in auto_init_wrapper
    return fn(*args, **kwargs)
  File "/Users/saisatyajonnalagadda/miniforge3/envs/carbFL/lib/python3.10/site-packages/ray/_private/client_mode_hook.py", line 103, in wrapper
    return func(*args, **kwargs)
  File "/Users/saisatyajonnalagadda/miniforge3/envs/carbFL/lib/python3.10/site-packages/ray/_private/worker.py", line 2524, in get
    raise value.as_instanceof_cause()
ray.exceptions.RayTaskError(ClientException): [36mray::DefaultActor.run()[39m (pid=93390, ip=127.0.0.1, actor_id=2660e0def9213d5d72ceb1f501000000, repr=<flwr.simulation.ray_transport.ray_actor.DefaultActor object at 0x11a80dff0>)
  File "/Users/saisatyajonnalagadda/current_projects/carb_aware_model_adaption_FL/main2.py", line 116, in client_fn
    trainloader=trainloaders[client_id],
IndexError: list index out of range

The above exception was the direct cause of the following exception:

[36mray::DefaultActor.run()[39m (pid=93390, ip=127.0.0.1, actor_id=2660e0def9213d5d72ceb1f501000000, repr=<flwr.simulation.ray_transport.ray_actor.DefaultActor object at 0x11a80dff0>)
  File "/Users/saisatyajonnalagadda/miniforge3/envs/carbFL/lib/python3.10/site-packages/flwr/simulation/ray_transport/ray_actor.py", line 84, in run
    raise ClientException(str(message)) from ex
flwr.simulation.ray_transport.ray_actor.ClientException: 
>>>>>>>A ClientException occurred.('\n\tSomething went wrong when running your client workload.\n\tClient 81_Sydney_large crashed when the DefaultActor was running its workload.\n\tException triggered on the client side: Traceback (most recent call last):\n  File "/Users/saisatyajonnalagadda/miniforge3/envs/carbFL/lib/python3.10/site-packages/flwr/simulation/ray_transport/ray_actor.py", line 70, in run\n    client = check_clientfn_returns_client(client_fn(cid))\n  File "/Users/saisatyajonnalagadda/current_projects/carb_aware_model_adaption_FL/main2.py", line 116, in client_fn\n    trainloader=trainloaders[client_id],\nIndexError: list index out of range\n',)

[2024-06-25 12:48:37,035][flwr][ERROR] - [36mray::DefaultActor.run()[39m (pid=93390, ip=127.0.0.1, actor_id=2660e0def9213d5d72ceb1f501000000, repr=<flwr.simulation.ray_transport.ray_actor.DefaultActor object at 0x11a80dff0>)
  File "/Users/saisatyajonnalagadda/current_projects/carb_aware_model_adaption_FL/main2.py", line 116, in client_fn
    trainloader=trainloaders[client_id],
IndexError: list index out of range

The above exception was the direct cause of the following exception:

[36mray::DefaultActor.run()[39m (pid=93390, ip=127.0.0.1, actor_id=2660e0def9213d5d72ceb1f501000000, repr=<flwr.simulation.ray_transport.ray_actor.DefaultActor object at 0x11a80dff0>)
  File "/Users/saisatyajonnalagadda/miniforge3/envs/carbFL/lib/python3.10/site-packages/flwr/simulation/ray_transport/ray_actor.py", line 84, in run
    raise ClientException(str(message)) from ex
flwr.simulation.ray_transport.ray_actor.ClientException: 
>>>>>>>A ClientException occurred.('\n\tSomething went wrong when running your client workload.\n\tClient 81_Sydney_large crashed when the DefaultActor was running its workload.\n\tException triggered on the client side: Traceback (most recent call last):\n  File "/Users/saisatyajonnalagadda/miniforge3/envs/carbFL/lib/python3.10/site-packages/flwr/simulation/ray_transport/ray_actor.py", line 70, in run\n    client = check_clientfn_returns_client(client_fn(cid))\n  File "/Users/saisatyajonnalagadda/current_projects/carb_aware_model_adaption_FL/main2.py", line 116, in client_fn\n    trainloader=trainloaders[client_id],\nIndexError: list index out of range\n',)
[2024-06-25 12:48:41,813][flwr][ERROR] - Traceback (most recent call last):
  File "/Users/saisatyajonnalagadda/miniforge3/envs/carbFL/lib/python3.10/site-packages/flwr/simulation/ray_transport/ray_client_proxy.py", line 138, in _submit_job
    res = self.actor_pool.get_client_result(self.cid, timeout)
  File "/Users/saisatyajonnalagadda/miniforge3/envs/carbFL/lib/python3.10/site-packages/flwr/simulation/ray_transport/ray_actor.py", line 414, in get_client_result
    return self._fetch_future_result(cid)
  File "/Users/saisatyajonnalagadda/miniforge3/envs/carbFL/lib/python3.10/site-packages/flwr/simulation/ray_transport/ray_actor.py", line 300, in _fetch_future_result
    res_cid, res = ray.get(future)  # type: (str, ClientRes)
  File "/Users/saisatyajonnalagadda/miniforge3/envs/carbFL/lib/python3.10/site-packages/ray/_private/auto_init_hook.py", line 24, in auto_init_wrapper
    return fn(*args, **kwargs)
  File "/Users/saisatyajonnalagadda/miniforge3/envs/carbFL/lib/python3.10/site-packages/ray/_private/client_mode_hook.py", line 103, in wrapper
    return func(*args, **kwargs)
  File "/Users/saisatyajonnalagadda/miniforge3/envs/carbFL/lib/python3.10/site-packages/ray/_private/worker.py", line 2524, in get
    raise value.as_instanceof_cause()
ray.exceptions.RayTaskError(ClientException): [36mray::DefaultActor.run()[39m (pid=93386, ip=127.0.0.1, actor_id=58e61da2bd71ea42dec983a401000000, repr=<flwr.simulation.ray_transport.ray_actor.DefaultActor object at 0x11120e080>)
  File "/Users/saisatyajonnalagadda/current_projects/carb_aware_model_adaption_FL/main2.py", line 116, in client_fn
    trainloader=trainloaders[client_id],
IndexError: list index out of range

The above exception was the direct cause of the following exception:

[36mray::DefaultActor.run()[39m (pid=93386, ip=127.0.0.1, actor_id=58e61da2bd71ea42dec983a401000000, repr=<flwr.simulation.ray_transport.ray_actor.DefaultActor object at 0x11120e080>)
  File "/Users/saisatyajonnalagadda/miniforge3/envs/carbFL/lib/python3.10/site-packages/flwr/simulation/ray_transport/ray_actor.py", line 84, in run
    raise ClientException(str(message)) from ex
flwr.simulation.ray_transport.ray_actor.ClientException: 
>>>>>>>A ClientException occurred.('\n\tSomething went wrong when running your client workload.\n\tClient 91_San Francisco_large crashed when the DefaultActor was running its workload.\n\tException triggered on the client side: Traceback (most recent call last):\n  File "/Users/saisatyajonnalagadda/miniforge3/envs/carbFL/lib/python3.10/site-packages/flwr/simulation/ray_transport/ray_actor.py", line 70, in run\n    client = check_clientfn_returns_client(client_fn(cid))\n  File "/Users/saisatyajonnalagadda/current_projects/carb_aware_model_adaption_FL/main2.py", line 116, in client_fn\n    trainloader=trainloaders[client_id],\nIndexError: list index out of range\n',)

[2024-06-25 12:48:41,833][flwr][ERROR] - [36mray::DefaultActor.run()[39m (pid=93386, ip=127.0.0.1, actor_id=58e61da2bd71ea42dec983a401000000, repr=<flwr.simulation.ray_transport.ray_actor.DefaultActor object at 0x11120e080>)
  File "/Users/saisatyajonnalagadda/current_projects/carb_aware_model_adaption_FL/main2.py", line 116, in client_fn
    trainloader=trainloaders[client_id],
IndexError: list index out of range

The above exception was the direct cause of the following exception:

[36mray::DefaultActor.run()[39m (pid=93386, ip=127.0.0.1, actor_id=58e61da2bd71ea42dec983a401000000, repr=<flwr.simulation.ray_transport.ray_actor.DefaultActor object at 0x11120e080>)
  File "/Users/saisatyajonnalagadda/miniforge3/envs/carbFL/lib/python3.10/site-packages/flwr/simulation/ray_transport/ray_actor.py", line 84, in run
    raise ClientException(str(message)) from ex
flwr.simulation.ray_transport.ray_actor.ClientException: 
>>>>>>>A ClientException occurred.('\n\tSomething went wrong when running your client workload.\n\tClient 91_San Francisco_large crashed when the DefaultActor was running its workload.\n\tException triggered on the client side: Traceback (most recent call last):\n  File "/Users/saisatyajonnalagadda/miniforge3/envs/carbFL/lib/python3.10/site-packages/flwr/simulation/ray_transport/ray_actor.py", line 70, in run\n    client = check_clientfn_returns_client(client_fn(cid))\n  File "/Users/saisatyajonnalagadda/current_projects/carb_aware_model_adaption_FL/main2.py", line 116, in client_fn\n    trainloader=trainloaders[client_id],\nIndexError: list index out of range\n',)
[2024-06-25 12:48:43,769][flwr][ERROR] - Traceback (most recent call last):
  File "/Users/saisatyajonnalagadda/miniforge3/envs/carbFL/lib/python3.10/site-packages/flwr/simulation/ray_transport/ray_client_proxy.py", line 138, in _submit_job
    res = self.actor_pool.get_client_result(self.cid, timeout)
  File "/Users/saisatyajonnalagadda/miniforge3/envs/carbFL/lib/python3.10/site-packages/flwr/simulation/ray_transport/ray_actor.py", line 414, in get_client_result
    return self._fetch_future_result(cid)
  File "/Users/saisatyajonnalagadda/miniforge3/envs/carbFL/lib/python3.10/site-packages/flwr/simulation/ray_transport/ray_actor.py", line 300, in _fetch_future_result
    res_cid, res = ray.get(future)  # type: (str, ClientRes)
  File "/Users/saisatyajonnalagadda/miniforge3/envs/carbFL/lib/python3.10/site-packages/ray/_private/auto_init_hook.py", line 24, in auto_init_wrapper
    return fn(*args, **kwargs)
  File "/Users/saisatyajonnalagadda/miniforge3/envs/carbFL/lib/python3.10/site-packages/ray/_private/client_mode_hook.py", line 103, in wrapper
    return func(*args, **kwargs)
  File "/Users/saisatyajonnalagadda/miniforge3/envs/carbFL/lib/python3.10/site-packages/ray/_private/worker.py", line 2524, in get
    raise value.as_instanceof_cause()
ray.exceptions.RayTaskError(ClientException): [36mray::DefaultActor.run()[39m (pid=93386, ip=127.0.0.1, actor_id=58e61da2bd71ea42dec983a401000000, repr=<flwr.simulation.ray_transport.ray_actor.DefaultActor object at 0x11120e080>)
  File "/Users/saisatyajonnalagadda/current_projects/carb_aware_model_adaption_FL/main2.py", line 116, in client_fn
    trainloader=trainloaders[client_id],
IndexError: list index out of range

The above exception was the direct cause of the following exception:

[36mray::DefaultActor.run()[39m (pid=93386, ip=127.0.0.1, actor_id=58e61da2bd71ea42dec983a401000000, repr=<flwr.simulation.ray_transport.ray_actor.DefaultActor object at 0x11120e080>)
  File "/Users/saisatyajonnalagadda/miniforge3/envs/carbFL/lib/python3.10/site-packages/flwr/simulation/ray_transport/ray_actor.py", line 84, in run
    raise ClientException(str(message)) from ex
flwr.simulation.ray_transport.ray_actor.ClientException: 
>>>>>>>A ClientException occurred.('\n\tSomething went wrong when running your client workload.\n\tClient 56_Hong Kong_mid crashed when the DefaultActor was running its workload.\n\tException triggered on the client side: Traceback (most recent call last):\n  File "/Users/saisatyajonnalagadda/miniforge3/envs/carbFL/lib/python3.10/site-packages/flwr/simulation/ray_transport/ray_actor.py", line 70, in run\n    client = check_clientfn_returns_client(client_fn(cid))\n  File "/Users/saisatyajonnalagadda/current_projects/carb_aware_model_adaption_FL/main2.py", line 116, in client_fn\n    trainloader=trainloaders[client_id],\nIndexError: list index out of range\n',)

[2024-06-25 12:48:43,796][flwr][ERROR] - [36mray::DefaultActor.run()[39m (pid=93386, ip=127.0.0.1, actor_id=58e61da2bd71ea42dec983a401000000, repr=<flwr.simulation.ray_transport.ray_actor.DefaultActor object at 0x11120e080>)
  File "/Users/saisatyajonnalagadda/current_projects/carb_aware_model_adaption_FL/main2.py", line 116, in client_fn
    trainloader=trainloaders[client_id],
IndexError: list index out of range

The above exception was the direct cause of the following exception:

[36mray::DefaultActor.run()[39m (pid=93386, ip=127.0.0.1, actor_id=58e61da2bd71ea42dec983a401000000, repr=<flwr.simulation.ray_transport.ray_actor.DefaultActor object at 0x11120e080>)
  File "/Users/saisatyajonnalagadda/miniforge3/envs/carbFL/lib/python3.10/site-packages/flwr/simulation/ray_transport/ray_actor.py", line 84, in run
    raise ClientException(str(message)) from ex
flwr.simulation.ray_transport.ray_actor.ClientException: 
>>>>>>>A ClientException occurred.('\n\tSomething went wrong when running your client workload.\n\tClient 56_Hong Kong_mid crashed when the DefaultActor was running its workload.\n\tException triggered on the client side: Traceback (most recent call last):\n  File "/Users/saisatyajonnalagadda/miniforge3/envs/carbFL/lib/python3.10/site-packages/flwr/simulation/ray_transport/ray_actor.py", line 70, in run\n    client = check_clientfn_returns_client(client_fn(cid))\n  File "/Users/saisatyajonnalagadda/current_projects/carb_aware_model_adaption_FL/main2.py", line 116, in client_fn\n    trainloader=trainloaders[client_id],\nIndexError: list index out of range\n',)
[2024-06-25 12:48:55,430][flwr][ERROR] - Traceback (most recent call last):
  File "/Users/saisatyajonnalagadda/miniforge3/envs/carbFL/lib/python3.10/site-packages/flwr/simulation/ray_transport/ray_client_proxy.py", line 138, in _submit_job
    res = self.actor_pool.get_client_result(self.cid, timeout)
  File "/Users/saisatyajonnalagadda/miniforge3/envs/carbFL/lib/python3.10/site-packages/flwr/simulation/ray_transport/ray_actor.py", line 414, in get_client_result
    return self._fetch_future_result(cid)
  File "/Users/saisatyajonnalagadda/miniforge3/envs/carbFL/lib/python3.10/site-packages/flwr/simulation/ray_transport/ray_actor.py", line 300, in _fetch_future_result
    res_cid, res = ray.get(future)  # type: (str, ClientRes)
  File "/Users/saisatyajonnalagadda/miniforge3/envs/carbFL/lib/python3.10/site-packages/ray/_private/auto_init_hook.py", line 24, in auto_init_wrapper
    return fn(*args, **kwargs)
  File "/Users/saisatyajonnalagadda/miniforge3/envs/carbFL/lib/python3.10/site-packages/ray/_private/client_mode_hook.py", line 103, in wrapper
    return func(*args, **kwargs)
  File "/Users/saisatyajonnalagadda/miniforge3/envs/carbFL/lib/python3.10/site-packages/ray/_private/worker.py", line 2524, in get
    raise value.as_instanceof_cause()
ray.exceptions.RayTaskError(ClientException): [36mray::DefaultActor.run()[39m (pid=93384, ip=127.0.0.1, actor_id=16813a4628b99ff15d870cfc01000000, repr=<flwr.simulation.ray_transport.ray_actor.DefaultActor object at 0x11c6fe020>)
  File "/Users/saisatyajonnalagadda/current_projects/carb_aware_model_adaption_FL/main2.py", line 116, in client_fn
    trainloader=trainloaders[client_id],
IndexError: list index out of range

The above exception was the direct cause of the following exception:

[36mray::DefaultActor.run()[39m (pid=93384, ip=127.0.0.1, actor_id=16813a4628b99ff15d870cfc01000000, repr=<flwr.simulation.ray_transport.ray_actor.DefaultActor object at 0x11c6fe020>)
  File "/Users/saisatyajonnalagadda/miniforge3/envs/carbFL/lib/python3.10/site-packages/flwr/simulation/ray_transport/ray_actor.py", line 84, in run
    raise ClientException(str(message)) from ex
flwr.simulation.ray_transport.ray_actor.ClientException: 
>>>>>>>A ClientException occurred.('\n\tSomething went wrong when running your client workload.\n\tClient 71_Sydney_mid crashed when the DefaultActor was running its workload.\n\tException triggered on the client side: Traceback (most recent call last):\n  File "/Users/saisatyajonnalagadda/miniforge3/envs/carbFL/lib/python3.10/site-packages/flwr/simulation/ray_transport/ray_actor.py", line 70, in run\n    client = check_clientfn_returns_client(client_fn(cid))\n  File "/Users/saisatyajonnalagadda/current_projects/carb_aware_model_adaption_FL/main2.py", line 116, in client_fn\n    trainloader=trainloaders[client_id],\nIndexError: list index out of range\n',)

[2024-06-25 12:48:55,430][flwr][ERROR] - Traceback (most recent call last):
  File "/Users/saisatyajonnalagadda/miniforge3/envs/carbFL/lib/python3.10/site-packages/flwr/simulation/ray_transport/ray_client_proxy.py", line 138, in _submit_job
    res = self.actor_pool.get_client_result(self.cid, timeout)
  File "/Users/saisatyajonnalagadda/miniforge3/envs/carbFL/lib/python3.10/site-packages/flwr/simulation/ray_transport/ray_actor.py", line 414, in get_client_result
    return self._fetch_future_result(cid)
  File "/Users/saisatyajonnalagadda/miniforge3/envs/carbFL/lib/python3.10/site-packages/flwr/simulation/ray_transport/ray_actor.py", line 300, in _fetch_future_result
    res_cid, res = ray.get(future)  # type: (str, ClientRes)
  File "/Users/saisatyajonnalagadda/miniforge3/envs/carbFL/lib/python3.10/site-packages/ray/_private/auto_init_hook.py", line 24, in auto_init_wrapper
    return fn(*args, **kwargs)
  File "/Users/saisatyajonnalagadda/miniforge3/envs/carbFL/lib/python3.10/site-packages/ray/_private/client_mode_hook.py", line 103, in wrapper
    return func(*args, **kwargs)
  File "/Users/saisatyajonnalagadda/miniforge3/envs/carbFL/lib/python3.10/site-packages/ray/_private/worker.py", line 2524, in get
    raise value.as_instanceof_cause()
ray.exceptions.RayTaskError(ClientException): [36mray::DefaultActor.run()[39m (pid=93386, ip=127.0.0.1, actor_id=58e61da2bd71ea42dec983a401000000, repr=<flwr.simulation.ray_transport.ray_actor.DefaultActor object at 0x11120e080>)
  File "/Users/saisatyajonnalagadda/current_projects/carb_aware_model_adaption_FL/main2.py", line 116, in client_fn
    trainloader=trainloaders[client_id],
IndexError: list index out of range

The above exception was the direct cause of the following exception:

[36mray::DefaultActor.run()[39m (pid=93386, ip=127.0.0.1, actor_id=58e61da2bd71ea42dec983a401000000, repr=<flwr.simulation.ray_transport.ray_actor.DefaultActor object at 0x11120e080>)
  File "/Users/saisatyajonnalagadda/miniforge3/envs/carbFL/lib/python3.10/site-packages/flwr/simulation/ray_transport/ray_actor.py", line 84, in run
    raise ClientException(str(message)) from ex
flwr.simulation.ray_transport.ray_actor.ClientException: 
>>>>>>>A ClientException occurred.('\n\tSomething went wrong when running your client workload.\n\tClient 87_San Francisco_mid crashed when the DefaultActor was running its workload.\n\tException triggered on the client side: Traceback (most recent call last):\n  File "/Users/saisatyajonnalagadda/miniforge3/envs/carbFL/lib/python3.10/site-packages/flwr/simulation/ray_transport/ray_actor.py", line 70, in run\n    client = check_clientfn_returns_client(client_fn(cid))\n  File "/Users/saisatyajonnalagadda/current_projects/carb_aware_model_adaption_FL/main2.py", line 116, in client_fn\n    trainloader=trainloaders[client_id],\nIndexError: list index out of range\n',)

[2024-06-25 12:48:55,456][flwr][ERROR] - [36mray::DefaultActor.run()[39m (pid=93384, ip=127.0.0.1, actor_id=16813a4628b99ff15d870cfc01000000, repr=<flwr.simulation.ray_transport.ray_actor.DefaultActor object at 0x11c6fe020>)
  File "/Users/saisatyajonnalagadda/current_projects/carb_aware_model_adaption_FL/main2.py", line 116, in client_fn
    trainloader=trainloaders[client_id],
IndexError: list index out of range

The above exception was the direct cause of the following exception:

[36mray::DefaultActor.run()[39m (pid=93384, ip=127.0.0.1, actor_id=16813a4628b99ff15d870cfc01000000, repr=<flwr.simulation.ray_transport.ray_actor.DefaultActor object at 0x11c6fe020>)
  File "/Users/saisatyajonnalagadda/miniforge3/envs/carbFL/lib/python3.10/site-packages/flwr/simulation/ray_transport/ray_actor.py", line 84, in run
    raise ClientException(str(message)) from ex
flwr.simulation.ray_transport.ray_actor.ClientException: 
>>>>>>>A ClientException occurred.('\n\tSomething went wrong when running your client workload.\n\tClient 71_Sydney_mid crashed when the DefaultActor was running its workload.\n\tException triggered on the client side: Traceback (most recent call last):\n  File "/Users/saisatyajonnalagadda/miniforge3/envs/carbFL/lib/python3.10/site-packages/flwr/simulation/ray_transport/ray_actor.py", line 70, in run\n    client = check_clientfn_returns_client(client_fn(cid))\n  File "/Users/saisatyajonnalagadda/current_projects/carb_aware_model_adaption_FL/main2.py", line 116, in client_fn\n    trainloader=trainloaders[client_id],\nIndexError: list index out of range\n',)
[2024-06-25 12:48:55,467][flwr][ERROR] - [36mray::DefaultActor.run()[39m (pid=93386, ip=127.0.0.1, actor_id=58e61da2bd71ea42dec983a401000000, repr=<flwr.simulation.ray_transport.ray_actor.DefaultActor object at 0x11120e080>)
  File "/Users/saisatyajonnalagadda/current_projects/carb_aware_model_adaption_FL/main2.py", line 116, in client_fn
    trainloader=trainloaders[client_id],
IndexError: list index out of range

The above exception was the direct cause of the following exception:

[36mray::DefaultActor.run()[39m (pid=93386, ip=127.0.0.1, actor_id=58e61da2bd71ea42dec983a401000000, repr=<flwr.simulation.ray_transport.ray_actor.DefaultActor object at 0x11120e080>)
  File "/Users/saisatyajonnalagadda/miniforge3/envs/carbFL/lib/python3.10/site-packages/flwr/simulation/ray_transport/ray_actor.py", line 84, in run
    raise ClientException(str(message)) from ex
flwr.simulation.ray_transport.ray_actor.ClientException: 
>>>>>>>A ClientException occurred.('\n\tSomething went wrong when running your client workload.\n\tClient 87_San Francisco_mid crashed when the DefaultActor was running its workload.\n\tException triggered on the client side: Traceback (most recent call last):\n  File "/Users/saisatyajonnalagadda/miniforge3/envs/carbFL/lib/python3.10/site-packages/flwr/simulation/ray_transport/ray_actor.py", line 70, in run\n    client = check_clientfn_returns_client(client_fn(cid))\n  File "/Users/saisatyajonnalagadda/current_projects/carb_aware_model_adaption_FL/main2.py", line 116, in client_fn\n    trainloader=trainloaders[client_id],\nIndexError: list index out of range\n',)
[2024-06-25 12:48:55,467][flwr][ERROR] - Traceback (most recent call last):
  File "/Users/saisatyajonnalagadda/miniforge3/envs/carbFL/lib/python3.10/site-packages/flwr/simulation/ray_transport/ray_client_proxy.py", line 138, in _submit_job
    res = self.actor_pool.get_client_result(self.cid, timeout)
  File "/Users/saisatyajonnalagadda/miniforge3/envs/carbFL/lib/python3.10/site-packages/flwr/simulation/ray_transport/ray_actor.py", line 414, in get_client_result
    return self._fetch_future_result(cid)
  File "/Users/saisatyajonnalagadda/miniforge3/envs/carbFL/lib/python3.10/site-packages/flwr/simulation/ray_transport/ray_actor.py", line 300, in _fetch_future_result
    res_cid, res = ray.get(future)  # type: (str, ClientRes)
  File "/Users/saisatyajonnalagadda/miniforge3/envs/carbFL/lib/python3.10/site-packages/ray/_private/auto_init_hook.py", line 24, in auto_init_wrapper
    return fn(*args, **kwargs)
  File "/Users/saisatyajonnalagadda/miniforge3/envs/carbFL/lib/python3.10/site-packages/ray/_private/client_mode_hook.py", line 103, in wrapper
    return func(*args, **kwargs)
  File "/Users/saisatyajonnalagadda/miniforge3/envs/carbFL/lib/python3.10/site-packages/ray/_private/worker.py", line 2524, in get
    raise value.as_instanceof_cause()
ray.exceptions.RayTaskError(ClientException): [36mray::DefaultActor.run()[39m (pid=93388, ip=127.0.0.1, actor_id=6e718db234739d23338590d901000000, repr=<flwr.simulation.ray_transport.ray_actor.DefaultActor object at 0x11220e020>)
  File "/Users/saisatyajonnalagadda/current_projects/carb_aware_model_adaption_FL/main2.py", line 116, in client_fn
    trainloader=trainloaders[client_id],
IndexError: list index out of range

The above exception was the direct cause of the following exception:

[36mray::DefaultActor.run()[39m (pid=93388, ip=127.0.0.1, actor_id=6e718db234739d23338590d901000000, repr=<flwr.simulation.ray_transport.ray_actor.DefaultActor object at 0x11220e020>)
  File "/Users/saisatyajonnalagadda/miniforge3/envs/carbFL/lib/python3.10/site-packages/flwr/simulation/ray_transport/ray_actor.py", line 84, in run
    raise ClientException(str(message)) from ex
flwr.simulation.ray_transport.ray_actor.ClientException: 
>>>>>>>A ClientException occurred.('\n\tSomething went wrong when running your client workload.\n\tClient 96_San Francisco_large crashed when the DefaultActor was running its workload.\n\tException triggered on the client side: Traceback (most recent call last):\n  File "/Users/saisatyajonnalagadda/miniforge3/envs/carbFL/lib/python3.10/site-packages/flwr/simulation/ray_transport/ray_actor.py", line 70, in run\n    client = check_clientfn_returns_client(client_fn(cid))\n  File "/Users/saisatyajonnalagadda/current_projects/carb_aware_model_adaption_FL/main2.py", line 116, in client_fn\n    trainloader=trainloaders[client_id],\nIndexError: list index out of range\n',)

[2024-06-25 12:48:55,498][flwr][ERROR] - [36mray::DefaultActor.run()[39m (pid=93388, ip=127.0.0.1, actor_id=6e718db234739d23338590d901000000, repr=<flwr.simulation.ray_transport.ray_actor.DefaultActor object at 0x11220e020>)
  File "/Users/saisatyajonnalagadda/current_projects/carb_aware_model_adaption_FL/main2.py", line 116, in client_fn
    trainloader=trainloaders[client_id],
IndexError: list index out of range

The above exception was the direct cause of the following exception:

[36mray::DefaultActor.run()[39m (pid=93388, ip=127.0.0.1, actor_id=6e718db234739d23338590d901000000, repr=<flwr.simulation.ray_transport.ray_actor.DefaultActor object at 0x11220e020>)
  File "/Users/saisatyajonnalagadda/miniforge3/envs/carbFL/lib/python3.10/site-packages/flwr/simulation/ray_transport/ray_actor.py", line 84, in run
    raise ClientException(str(message)) from ex
flwr.simulation.ray_transport.ray_actor.ClientException: 
>>>>>>>A ClientException occurred.('\n\tSomething went wrong when running your client workload.\n\tClient 96_San Francisco_large crashed when the DefaultActor was running its workload.\n\tException triggered on the client side: Traceback (most recent call last):\n  File "/Users/saisatyajonnalagadda/miniforge3/envs/carbFL/lib/python3.10/site-packages/flwr/simulation/ray_transport/ray_actor.py", line 70, in run\n    client = check_clientfn_returns_client(client_fn(cid))\n  File "/Users/saisatyajonnalagadda/current_projects/carb_aware_model_adaption_FL/main2.py", line 116, in client_fn\n    trainloader=trainloaders[client_id],\nIndexError: list index out of range\n',)
[2024-06-25 12:48:58,950][flwr][ERROR] - Traceback (most recent call last):
  File "/Users/saisatyajonnalagadda/miniforge3/envs/carbFL/lib/python3.10/site-packages/flwr/simulation/ray_transport/ray_client_proxy.py", line 138, in _submit_job
    res = self.actor_pool.get_client_result(self.cid, timeout)
  File "/Users/saisatyajonnalagadda/miniforge3/envs/carbFL/lib/python3.10/site-packages/flwr/simulation/ray_transport/ray_actor.py", line 414, in get_client_result
    return self._fetch_future_result(cid)
  File "/Users/saisatyajonnalagadda/miniforge3/envs/carbFL/lib/python3.10/site-packages/flwr/simulation/ray_transport/ray_actor.py", line 300, in _fetch_future_result
    res_cid, res = ray.get(future)  # type: (str, ClientRes)
  File "/Users/saisatyajonnalagadda/miniforge3/envs/carbFL/lib/python3.10/site-packages/ray/_private/auto_init_hook.py", line 24, in auto_init_wrapper
    return fn(*args, **kwargs)
  File "/Users/saisatyajonnalagadda/miniforge3/envs/carbFL/lib/python3.10/site-packages/ray/_private/client_mode_hook.py", line 103, in wrapper
    return func(*args, **kwargs)
  File "/Users/saisatyajonnalagadda/miniforge3/envs/carbFL/lib/python3.10/site-packages/ray/_private/worker.py", line 2524, in get
    raise value.as_instanceof_cause()
ray.exceptions.RayTaskError(ClientException): [36mray::DefaultActor.run()[39m (pid=93387, ip=127.0.0.1, actor_id=4e1a7e7e47b698299e1b387101000000, repr=<flwr.simulation.ray_transport.ray_actor.DefaultActor object at 0x1158d1ff0>)
  File "/Users/saisatyajonnalagadda/current_projects/carb_aware_model_adaption_FL/main2.py", line 116, in client_fn
    trainloader=trainloaders[client_id],
IndexError: list index out of range

The above exception was the direct cause of the following exception:

[36mray::DefaultActor.run()[39m (pid=93387, ip=127.0.0.1, actor_id=4e1a7e7e47b698299e1b387101000000, repr=<flwr.simulation.ray_transport.ray_actor.DefaultActor object at 0x1158d1ff0>)
  File "/Users/saisatyajonnalagadda/miniforge3/envs/carbFL/lib/python3.10/site-packages/flwr/simulation/ray_transport/ray_actor.py", line 84, in run
    raise ClientException(str(message)) from ex
flwr.simulation.ray_transport.ray_actor.ClientException: 
>>>>>>>A ClientException occurred.('\n\tSomething went wrong when running your client workload.\n\tClient 78_San Francisco_mid crashed when the DefaultActor was running its workload.\n\tException triggered on the client side: Traceback (most recent call last):\n  File "/Users/saisatyajonnalagadda/miniforge3/envs/carbFL/lib/python3.10/site-packages/flwr/simulation/ray_transport/ray_actor.py", line 70, in run\n    client = check_clientfn_returns_client(client_fn(cid))\n  File "/Users/saisatyajonnalagadda/current_projects/carb_aware_model_adaption_FL/main2.py", line 116, in client_fn\n    trainloader=trainloaders[client_id],\nIndexError: list index out of range\n',)

[2024-06-25 12:48:58,980][flwr][ERROR] - [36mray::DefaultActor.run()[39m (pid=93387, ip=127.0.0.1, actor_id=4e1a7e7e47b698299e1b387101000000, repr=<flwr.simulation.ray_transport.ray_actor.DefaultActor object at 0x1158d1ff0>)
  File "/Users/saisatyajonnalagadda/current_projects/carb_aware_model_adaption_FL/main2.py", line 116, in client_fn
    trainloader=trainloaders[client_id],
IndexError: list index out of range

The above exception was the direct cause of the following exception:

[36mray::DefaultActor.run()[39m (pid=93387, ip=127.0.0.1, actor_id=4e1a7e7e47b698299e1b387101000000, repr=<flwr.simulation.ray_transport.ray_actor.DefaultActor object at 0x1158d1ff0>)
  File "/Users/saisatyajonnalagadda/miniforge3/envs/carbFL/lib/python3.10/site-packages/flwr/simulation/ray_transport/ray_actor.py", line 84, in run
    raise ClientException(str(message)) from ex
flwr.simulation.ray_transport.ray_actor.ClientException: 
>>>>>>>A ClientException occurred.('\n\tSomething went wrong when running your client workload.\n\tClient 78_San Francisco_mid crashed when the DefaultActor was running its workload.\n\tException triggered on the client side: Traceback (most recent call last):\n  File "/Users/saisatyajonnalagadda/miniforge3/envs/carbFL/lib/python3.10/site-packages/flwr/simulation/ray_transport/ray_actor.py", line 70, in run\n    client = check_clientfn_returns_client(client_fn(cid))\n  File "/Users/saisatyajonnalagadda/current_projects/carb_aware_model_adaption_FL/main2.py", line 116, in client_fn\n    trainloader=trainloaders[client_id],\nIndexError: list index out of range\n',)
[2024-06-25 12:49:10,163][flwr][ERROR] - Traceback (most recent call last):
  File "/Users/saisatyajonnalagadda/miniforge3/envs/carbFL/lib/python3.10/site-packages/flwr/simulation/ray_transport/ray_client_proxy.py", line 134, in _submit_job
    self.actor_pool.submit_client_job(
  File "/Users/saisatyajonnalagadda/miniforge3/envs/carbFL/lib/python3.10/site-packages/flwr/simulation/ray_transport/ray_actor.py", line 265, in submit_client_job
    self.submit(actor_fn, job)
  File "/Users/saisatyajonnalagadda/miniforge3/envs/carbFL/lib/python3.10/site-packages/flwr/simulation/ray_transport/ray_actor.py", line 243, in submit
    future = fn(actor, client_fn, job_fn, cid)
  File "/Users/saisatyajonnalagadda/miniforge3/envs/carbFL/lib/python3.10/site-packages/flwr/simulation/ray_transport/ray_client_proxy.py", line 135, in <lambda>
    lambda a, c_fn, j_fn, cid: a.run.remote(c_fn, j_fn, cid),
  File "/Users/saisatyajonnalagadda/miniforge3/envs/carbFL/lib/python3.10/site-packages/ray/actor.py", line 144, in remote
    return self._remote(args, kwargs)
  File "/Users/saisatyajonnalagadda/miniforge3/envs/carbFL/lib/python3.10/site-packages/ray/util/tracing/tracing_helper.py", line 423, in _start_span
    return method(self, args, kwargs, *_args, **_kwargs)
  File "/Users/saisatyajonnalagadda/miniforge3/envs/carbFL/lib/python3.10/site-packages/ray/actor.py", line 190, in _remote
    return invocation(args, kwargs)
  File "/Users/saisatyajonnalagadda/miniforge3/envs/carbFL/lib/python3.10/site-packages/ray/actor.py", line 177, in invocation
    return actor._actor_method_call(
  File "/Users/saisatyajonnalagadda/miniforge3/envs/carbFL/lib/python3.10/site-packages/ray/actor.py", line 1175, in _actor_method_call
    object_refs = worker.core_worker.submit_actor_task(
  File "python/ray/_raylet.pyx", line 3350, in ray._raylet.CoreWorker.submit_actor_task
  File "python/ray/_raylet.pyx", line 3355, in ray._raylet.CoreWorker.submit_actor_task
  File "python/ray/_raylet.pyx", line 649, in ray._raylet.prepare_args_and_increment_put_refs
  File "python/ray/_raylet.pyx", line 640, in ray._raylet.prepare_args_and_increment_put_refs
  File "python/ray/_raylet.pyx", line 734, in ray._raylet.prepare_args_internal
  File "python/ray/_raylet.pyx", line 2939, in ray._raylet.CoreWorker.put_serialized_object_and_increment_local_ref
  File "python/ray/_raylet.pyx", line 2831, in ray._raylet.CoreWorker._create_put_buffer
  File "python/ray/_raylet.pyx", line 396, in ray._raylet.check_status
ray.exceptions.OutOfDiskError: Local disk is full
The object cannot be created because the local object store is full and the local disk's utilization is over capacity (95% by default).Tip: Use `df` on this node to check disk usage and `ray memory` to check object store memory usage.

[2024-06-25 12:49:10,166][flwr][ERROR] - Local disk is full
The object cannot be created because the local object store is full and the local disk's utilization is over capacity (95% by default).Tip: Use `df` on this node to check disk usage and `ray memory` to check object store memory usage.
[2024-06-25 12:49:12,117][flwr][ERROR] - Traceback (most recent call last):
  File "/Users/saisatyajonnalagadda/miniforge3/envs/carbFL/lib/python3.10/site-packages/flwr/simulation/ray_transport/ray_client_proxy.py", line 134, in _submit_job
    self.actor_pool.submit_client_job(
  File "/Users/saisatyajonnalagadda/miniforge3/envs/carbFL/lib/python3.10/site-packages/flwr/simulation/ray_transport/ray_actor.py", line 265, in submit_client_job
    self.submit(actor_fn, job)
  File "/Users/saisatyajonnalagadda/miniforge3/envs/carbFL/lib/python3.10/site-packages/flwr/simulation/ray_transport/ray_actor.py", line 243, in submit
    future = fn(actor, client_fn, job_fn, cid)
  File "/Users/saisatyajonnalagadda/miniforge3/envs/carbFL/lib/python3.10/site-packages/flwr/simulation/ray_transport/ray_client_proxy.py", line 135, in <lambda>
    lambda a, c_fn, j_fn, cid: a.run.remote(c_fn, j_fn, cid),
  File "/Users/saisatyajonnalagadda/miniforge3/envs/carbFL/lib/python3.10/site-packages/ray/actor.py", line 144, in remote
    return self._remote(args, kwargs)
  File "/Users/saisatyajonnalagadda/miniforge3/envs/carbFL/lib/python3.10/site-packages/ray/util/tracing/tracing_helper.py", line 423, in _start_span
    return method(self, args, kwargs, *_args, **_kwargs)
  File "/Users/saisatyajonnalagadda/miniforge3/envs/carbFL/lib/python3.10/site-packages/ray/actor.py", line 190, in _remote
    return invocation(args, kwargs)
  File "/Users/saisatyajonnalagadda/miniforge3/envs/carbFL/lib/python3.10/site-packages/ray/actor.py", line 177, in invocation
    return actor._actor_method_call(
  File "/Users/saisatyajonnalagadda/miniforge3/envs/carbFL/lib/python3.10/site-packages/ray/actor.py", line 1175, in _actor_method_call
    object_refs = worker.core_worker.submit_actor_task(
  File "python/ray/_raylet.pyx", line 3350, in ray._raylet.CoreWorker.submit_actor_task
  File "python/ray/_raylet.pyx", line 3355, in ray._raylet.CoreWorker.submit_actor_task
  File "python/ray/_raylet.pyx", line 649, in ray._raylet.prepare_args_and_increment_put_refs
  File "python/ray/_raylet.pyx", line 640, in ray._raylet.prepare_args_and_increment_put_refs
  File "python/ray/_raylet.pyx", line 734, in ray._raylet.prepare_args_internal
  File "python/ray/_raylet.pyx", line 2939, in ray._raylet.CoreWorker.put_serialized_object_and_increment_local_ref
  File "python/ray/_raylet.pyx", line 2831, in ray._raylet.CoreWorker._create_put_buffer
  File "python/ray/_raylet.pyx", line 396, in ray._raylet.check_status
ray.exceptions.OutOfDiskError: Local disk is full
The object cannot be created because the local object store is full and the local disk's utilization is over capacity (95% by default).Tip: Use `df` on this node to check disk usage and `ray memory` to check object store memory usage.

[2024-06-25 12:49:12,142][flwr][ERROR] - Local disk is full
The object cannot be created because the local object store is full and the local disk's utilization is over capacity (95% by default).Tip: Use `df` on this node to check disk usage and `ray memory` to check object store memory usage.
[2024-06-25 12:49:13,079][flwr][ERROR] - Traceback (most recent call last):
  File "/Users/saisatyajonnalagadda/miniforge3/envs/carbFL/lib/python3.10/site-packages/flwr/simulation/ray_transport/ray_client_proxy.py", line 134, in _submit_job
    self.actor_pool.submit_client_job(
  File "/Users/saisatyajonnalagadda/miniforge3/envs/carbFL/lib/python3.10/site-packages/flwr/simulation/ray_transport/ray_actor.py", line 265, in submit_client_job
    self.submit(actor_fn, job)
  File "/Users/saisatyajonnalagadda/miniforge3/envs/carbFL/lib/python3.10/site-packages/flwr/simulation/ray_transport/ray_actor.py", line 243, in submit
    future = fn(actor, client_fn, job_fn, cid)
  File "/Users/saisatyajonnalagadda/miniforge3/envs/carbFL/lib/python3.10/site-packages/flwr/simulation/ray_transport/ray_client_proxy.py", line 135, in <lambda>
    lambda a, c_fn, j_fn, cid: a.run.remote(c_fn, j_fn, cid),
  File "/Users/saisatyajonnalagadda/miniforge3/envs/carbFL/lib/python3.10/site-packages/ray/actor.py", line 144, in remote
    return self._remote(args, kwargs)
  File "/Users/saisatyajonnalagadda/miniforge3/envs/carbFL/lib/python3.10/site-packages/ray/util/tracing/tracing_helper.py", line 423, in _start_span
    return method(self, args, kwargs, *_args, **_kwargs)
  File "/Users/saisatyajonnalagadda/miniforge3/envs/carbFL/lib/python3.10/site-packages/ray/actor.py", line 190, in _remote
    return invocation(args, kwargs)
  File "/Users/saisatyajonnalagadda/miniforge3/envs/carbFL/lib/python3.10/site-packages/ray/actor.py", line 177, in invocation
    return actor._actor_method_call(
  File "/Users/saisatyajonnalagadda/miniforge3/envs/carbFL/lib/python3.10/site-packages/ray/actor.py", line 1175, in _actor_method_call
    object_refs = worker.core_worker.submit_actor_task(
  File "python/ray/_raylet.pyx", line 3350, in ray._raylet.CoreWorker.submit_actor_task
  File "python/ray/_raylet.pyx", line 3355, in ray._raylet.CoreWorker.submit_actor_task
  File "python/ray/_raylet.pyx", line 649, in ray._raylet.prepare_args_and_increment_put_refs
  File "python/ray/_raylet.pyx", line 640, in ray._raylet.prepare_args_and_increment_put_refs
  File "python/ray/_raylet.pyx", line 734, in ray._raylet.prepare_args_internal
  File "python/ray/_raylet.pyx", line 2939, in ray._raylet.CoreWorker.put_serialized_object_and_increment_local_ref
  File "python/ray/_raylet.pyx", line 2831, in ray._raylet.CoreWorker._create_put_buffer
  File "python/ray/_raylet.pyx", line 396, in ray._raylet.check_status
ray.exceptions.OutOfDiskError: Local disk is full
The object cannot be created because the local object store is full and the local disk's utilization is over capacity (95% by default).Tip: Use `df` on this node to check disk usage and `ray memory` to check object store memory usage.

[2024-06-25 12:49:13,098][flwr][ERROR] - Local disk is full
The object cannot be created because the local object store is full and the local disk's utilization is over capacity (95% by default).Tip: Use `df` on this node to check disk usage and `ray memory` to check object store memory usage.
[2024-06-25 12:49:23,653][flwr][ERROR] - Traceback (most recent call last):
  File "/Users/saisatyajonnalagadda/miniforge3/envs/carbFL/lib/python3.10/site-packages/flwr/simulation/ray_transport/ray_client_proxy.py", line 138, in _submit_job
    res = self.actor_pool.get_client_result(self.cid, timeout)
  File "/Users/saisatyajonnalagadda/miniforge3/envs/carbFL/lib/python3.10/site-packages/flwr/simulation/ray_transport/ray_actor.py", line 414, in get_client_result
    return self._fetch_future_result(cid)
  File "/Users/saisatyajonnalagadda/miniforge3/envs/carbFL/lib/python3.10/site-packages/flwr/simulation/ray_transport/ray_actor.py", line 300, in _fetch_future_result
    res_cid, res = ray.get(future)  # type: (str, ClientRes)
  File "/Users/saisatyajonnalagadda/miniforge3/envs/carbFL/lib/python3.10/site-packages/ray/_private/auto_init_hook.py", line 24, in auto_init_wrapper
    return fn(*args, **kwargs)
  File "/Users/saisatyajonnalagadda/miniforge3/envs/carbFL/lib/python3.10/site-packages/ray/_private/client_mode_hook.py", line 103, in wrapper
    return func(*args, **kwargs)
  File "/Users/saisatyajonnalagadda/miniforge3/envs/carbFL/lib/python3.10/site-packages/ray/_private/worker.py", line 2524, in get
    raise value.as_instanceof_cause()
ray.exceptions.RayTaskError(ClientException): [36mray::DefaultActor.run()[39m (pid=93384, ip=127.0.0.1, actor_id=16813a4628b99ff15d870cfc01000000, repr=<flwr.simulation.ray_transport.ray_actor.DefaultActor object at 0x11c6fe020>)
  File "/Users/saisatyajonnalagadda/current_projects/carb_aware_model_adaption_FL/main2.py", line 116, in client_fn
    trainloader=trainloaders[client_id],
IndexError: list index out of range

The above exception was the direct cause of the following exception:

[36mray::DefaultActor.run()[39m (pid=93384, ip=127.0.0.1, actor_id=16813a4628b99ff15d870cfc01000000, repr=<flwr.simulation.ray_transport.ray_actor.DefaultActor object at 0x11c6fe020>)
  File "/Users/saisatyajonnalagadda/miniforge3/envs/carbFL/lib/python3.10/site-packages/flwr/simulation/ray_transport/ray_actor.py", line 84, in run
    raise ClientException(str(message)) from ex
flwr.simulation.ray_transport.ray_actor.ClientException: 
>>>>>>>A ClientException occurred.('\n\tSomething went wrong when running your client workload.\n\tClient 92_San Francisco_mid crashed when the DefaultActor was running its workload.\n\tException triggered on the client side: Traceback (most recent call last):\n  File "/Users/saisatyajonnalagadda/miniforge3/envs/carbFL/lib/python3.10/site-packages/flwr/simulation/ray_transport/ray_actor.py", line 70, in run\n    client = check_clientfn_returns_client(client_fn(cid))\n  File "/Users/saisatyajonnalagadda/current_projects/carb_aware_model_adaption_FL/main2.py", line 116, in client_fn\n    trainloader=trainloaders[client_id],\nIndexError: list index out of range\n',)

[2024-06-25 12:49:23,674][flwr][ERROR] - [36mray::DefaultActor.run()[39m (pid=93384, ip=127.0.0.1, actor_id=16813a4628b99ff15d870cfc01000000, repr=<flwr.simulation.ray_transport.ray_actor.DefaultActor object at 0x11c6fe020>)
  File "/Users/saisatyajonnalagadda/current_projects/carb_aware_model_adaption_FL/main2.py", line 116, in client_fn
    trainloader=trainloaders[client_id],
IndexError: list index out of range

The above exception was the direct cause of the following exception:

[36mray::DefaultActor.run()[39m (pid=93384, ip=127.0.0.1, actor_id=16813a4628b99ff15d870cfc01000000, repr=<flwr.simulation.ray_transport.ray_actor.DefaultActor object at 0x11c6fe020>)
  File "/Users/saisatyajonnalagadda/miniforge3/envs/carbFL/lib/python3.10/site-packages/flwr/simulation/ray_transport/ray_actor.py", line 84, in run
    raise ClientException(str(message)) from ex
flwr.simulation.ray_transport.ray_actor.ClientException: 
>>>>>>>A ClientException occurred.('\n\tSomething went wrong when running your client workload.\n\tClient 92_San Francisco_mid crashed when the DefaultActor was running its workload.\n\tException triggered on the client side: Traceback (most recent call last):\n  File "/Users/saisatyajonnalagadda/miniforge3/envs/carbFL/lib/python3.10/site-packages/flwr/simulation/ray_transport/ray_actor.py", line 70, in run\n    client = check_clientfn_returns_client(client_fn(cid))\n  File "/Users/saisatyajonnalagadda/current_projects/carb_aware_model_adaption_FL/main2.py", line 116, in client_fn\n    trainloader=trainloaders[client_id],\nIndexError: list index out of range\n',)
[2024-06-25 12:49:33,667][flwr][ERROR] - Traceback (most recent call last):
  File "/Users/saisatyajonnalagadda/miniforge3/envs/carbFL/lib/python3.10/site-packages/flwr/simulation/ray_transport/ray_client_proxy.py", line 138, in _submit_job
    res = self.actor_pool.get_client_result(self.cid, timeout)
  File "/Users/saisatyajonnalagadda/miniforge3/envs/carbFL/lib/python3.10/site-packages/flwr/simulation/ray_transport/ray_actor.py", line 408, in get_client_result
    self.process_unordered_future(timeout=timeout)
  File "/Users/saisatyajonnalagadda/miniforge3/envs/carbFL/lib/python3.10/site-packages/flwr/simulation/ray_transport/ray_actor.py", line 392, in process_unordered_future
    self._return_actor(actor)  # type: ignore
  File "/Users/saisatyajonnalagadda/miniforge3/envs/carbFL/lib/python3.10/site-packages/ray/util/actor_pool.py", line 366, in _return_actor
    self.submit(*self._pending_submits.pop(0))
  File "/Users/saisatyajonnalagadda/miniforge3/envs/carbFL/lib/python3.10/site-packages/flwr/simulation/ray_transport/ray_actor.py", line 243, in submit
    future = fn(actor, client_fn, job_fn, cid)
  File "/Users/saisatyajonnalagadda/miniforge3/envs/carbFL/lib/python3.10/site-packages/flwr/simulation/ray_transport/ray_client_proxy.py", line 135, in <lambda>
    lambda a, c_fn, j_fn, cid: a.run.remote(c_fn, j_fn, cid),
  File "/Users/saisatyajonnalagadda/miniforge3/envs/carbFL/lib/python3.10/site-packages/ray/actor.py", line 144, in remote
    return self._remote(args, kwargs)
  File "/Users/saisatyajonnalagadda/miniforge3/envs/carbFL/lib/python3.10/site-packages/ray/util/tracing/tracing_helper.py", line 423, in _start_span
    return method(self, args, kwargs, *_args, **_kwargs)
  File "/Users/saisatyajonnalagadda/miniforge3/envs/carbFL/lib/python3.10/site-packages/ray/actor.py", line 190, in _remote
    return invocation(args, kwargs)
  File "/Users/saisatyajonnalagadda/miniforge3/envs/carbFL/lib/python3.10/site-packages/ray/actor.py", line 177, in invocation
    return actor._actor_method_call(
  File "/Users/saisatyajonnalagadda/miniforge3/envs/carbFL/lib/python3.10/site-packages/ray/actor.py", line 1175, in _actor_method_call
    object_refs = worker.core_worker.submit_actor_task(
  File "python/ray/_raylet.pyx", line 3350, in ray._raylet.CoreWorker.submit_actor_task
  File "python/ray/_raylet.pyx", line 3355, in ray._raylet.CoreWorker.submit_actor_task
  File "python/ray/_raylet.pyx", line 649, in ray._raylet.prepare_args_and_increment_put_refs
  File "python/ray/_raylet.pyx", line 640, in ray._raylet.prepare_args_and_increment_put_refs
  File "python/ray/_raylet.pyx", line 734, in ray._raylet.prepare_args_internal
  File "python/ray/_raylet.pyx", line 2939, in ray._raylet.CoreWorker.put_serialized_object_and_increment_local_ref
  File "python/ray/_raylet.pyx", line 2831, in ray._raylet.CoreWorker._create_put_buffer
  File "python/ray/_raylet.pyx", line 396, in ray._raylet.check_status
ray.exceptions.OutOfDiskError: Local disk is full
The object cannot be created because the local object store is full and the local disk's utilization is over capacity (95% by default).Tip: Use `df` on this node to check disk usage and `ray memory` to check object store memory usage.

[2024-06-25 12:49:33,724][flwr][ERROR] - Local disk is full
The object cannot be created because the local object store is full and the local disk's utilization is over capacity (95% by default).Tip: Use `df` on this node to check disk usage and `ray memory` to check object store memory usage.
[2024-06-25 12:49:35,943][flwr][ERROR] - Traceback (most recent call last):
  File "/Users/saisatyajonnalagadda/miniforge3/envs/carbFL/lib/python3.10/site-packages/flwr/simulation/ray_transport/ray_client_proxy.py", line 138, in _submit_job
    res = self.actor_pool.get_client_result(self.cid, timeout)
  File "/Users/saisatyajonnalagadda/miniforge3/envs/carbFL/lib/python3.10/site-packages/flwr/simulation/ray_transport/ray_actor.py", line 414, in get_client_result
    return self._fetch_future_result(cid)
  File "/Users/saisatyajonnalagadda/miniforge3/envs/carbFL/lib/python3.10/site-packages/flwr/simulation/ray_transport/ray_actor.py", line 300, in _fetch_future_result
    res_cid, res = ray.get(future)  # type: (str, ClientRes)
  File "/Users/saisatyajonnalagadda/miniforge3/envs/carbFL/lib/python3.10/site-packages/ray/_private/auto_init_hook.py", line 24, in auto_init_wrapper
    return fn(*args, **kwargs)
  File "/Users/saisatyajonnalagadda/miniforge3/envs/carbFL/lib/python3.10/site-packages/ray/_private/client_mode_hook.py", line 103, in wrapper
    return func(*args, **kwargs)
  File "/Users/saisatyajonnalagadda/miniforge3/envs/carbFL/lib/python3.10/site-packages/ray/_private/worker.py", line 2524, in get
    raise value.as_instanceof_cause()
ray.exceptions.RayTaskError(ClientException): [36mray::DefaultActor.run()[39m (pid=93388, ip=127.0.0.1, actor_id=6e718db234739d23338590d901000000, repr=<flwr.simulation.ray_transport.ray_actor.DefaultActor object at 0x11220e020>)
  File "/Users/saisatyajonnalagadda/current_projects/carb_aware_model_adaption_FL/main2.py", line 116, in client_fn
    trainloader=trainloaders[client_id],
IndexError: list index out of range

The above exception was the direct cause of the following exception:

[36mray::DefaultActor.run()[39m (pid=93388, ip=127.0.0.1, actor_id=6e718db234739d23338590d901000000, repr=<flwr.simulation.ray_transport.ray_actor.DefaultActor object at 0x11220e020>)
  File "/Users/saisatyajonnalagadda/miniforge3/envs/carbFL/lib/python3.10/site-packages/flwr/simulation/ray_transport/ray_actor.py", line 84, in run
    raise ClientException(str(message)) from ex
flwr.simulation.ray_transport.ray_actor.ClientException: 
>>>>>>>A ClientException occurred.('\n\tSomething went wrong when running your client workload.\n\tClient 84_Mexico City_small crashed when the DefaultActor was running its workload.\n\tException triggered on the client side: Traceback (most recent call last):\n  File "/Users/saisatyajonnalagadda/miniforge3/envs/carbFL/lib/python3.10/site-packages/flwr/simulation/ray_transport/ray_actor.py", line 70, in run\n    client = check_clientfn_returns_client(client_fn(cid))\n  File "/Users/saisatyajonnalagadda/current_projects/carb_aware_model_adaption_FL/main2.py", line 116, in client_fn\n    trainloader=trainloaders[client_id],\nIndexError: list index out of range\n',)

[2024-06-25 12:49:35,943][flwr][ERROR] - Traceback (most recent call last):
  File "/Users/saisatyajonnalagadda/miniforge3/envs/carbFL/lib/python3.10/site-packages/flwr/simulation/ray_transport/ray_client_proxy.py", line 138, in _submit_job
    res = self.actor_pool.get_client_result(self.cid, timeout)
  File "/Users/saisatyajonnalagadda/miniforge3/envs/carbFL/lib/python3.10/site-packages/flwr/simulation/ray_transport/ray_actor.py", line 414, in get_client_result
    return self._fetch_future_result(cid)
  File "/Users/saisatyajonnalagadda/miniforge3/envs/carbFL/lib/python3.10/site-packages/flwr/simulation/ray_transport/ray_actor.py", line 300, in _fetch_future_result
    res_cid, res = ray.get(future)  # type: (str, ClientRes)
  File "/Users/saisatyajonnalagadda/miniforge3/envs/carbFL/lib/python3.10/site-packages/ray/_private/auto_init_hook.py", line 24, in auto_init_wrapper
    return fn(*args, **kwargs)
  File "/Users/saisatyajonnalagadda/miniforge3/envs/carbFL/lib/python3.10/site-packages/ray/_private/client_mode_hook.py", line 103, in wrapper
    return func(*args, **kwargs)
  File "/Users/saisatyajonnalagadda/miniforge3/envs/carbFL/lib/python3.10/site-packages/ray/_private/worker.py", line 2524, in get
    raise value.as_instanceof_cause()
ray.exceptions.RayTaskError(ClientException): [36mray::DefaultActor.run()[39m (pid=93386, ip=127.0.0.1, actor_id=58e61da2bd71ea42dec983a401000000, repr=<flwr.simulation.ray_transport.ray_actor.DefaultActor object at 0x11120e080>)
  File "/Users/saisatyajonnalagadda/current_projects/carb_aware_model_adaption_FL/main2.py", line 116, in client_fn
    trainloader=trainloaders[client_id],
IndexError: list index out of range

The above exception was the direct cause of the following exception:

[36mray::DefaultActor.run()[39m (pid=93386, ip=127.0.0.1, actor_id=58e61da2bd71ea42dec983a401000000, repr=<flwr.simulation.ray_transport.ray_actor.DefaultActor object at 0x11120e080>)
  File "/Users/saisatyajonnalagadda/miniforge3/envs/carbFL/lib/python3.10/site-packages/flwr/simulation/ray_transport/ray_actor.py", line 84, in run
    raise ClientException(str(message)) from ex
flwr.simulation.ray_transport.ray_actor.ClientException: 
>>>>>>>A ClientException occurred.('\n\tSomething went wrong when running your client workload.\n\tClient 73_Mexico City_small crashed when the DefaultActor was running its workload.\n\tException triggered on the client side: Traceback (most recent call last):\n  File "/Users/saisatyajonnalagadda/miniforge3/envs/carbFL/lib/python3.10/site-packages/flwr/simulation/ray_transport/ray_actor.py", line 70, in run\n    client = check_clientfn_returns_client(client_fn(cid))\n  File "/Users/saisatyajonnalagadda/current_projects/carb_aware_model_adaption_FL/main2.py", line 116, in client_fn\n    trainloader=trainloaders[client_id],\nIndexError: list index out of range\n',)

[2024-06-25 12:49:35,944][flwr][ERROR] - Traceback (most recent call last):
  File "/Users/saisatyajonnalagadda/miniforge3/envs/carbFL/lib/python3.10/site-packages/flwr/simulation/ray_transport/ray_client_proxy.py", line 138, in _submit_job
    res = self.actor_pool.get_client_result(self.cid, timeout)
  File "/Users/saisatyajonnalagadda/miniforge3/envs/carbFL/lib/python3.10/site-packages/flwr/simulation/ray_transport/ray_actor.py", line 414, in get_client_result
    return self._fetch_future_result(cid)
  File "/Users/saisatyajonnalagadda/miniforge3/envs/carbFL/lib/python3.10/site-packages/flwr/simulation/ray_transport/ray_actor.py", line 300, in _fetch_future_result
    res_cid, res = ray.get(future)  # type: (str, ClientRes)
  File "/Users/saisatyajonnalagadda/miniforge3/envs/carbFL/lib/python3.10/site-packages/ray/_private/auto_init_hook.py", line 24, in auto_init_wrapper
    return fn(*args, **kwargs)
  File "/Users/saisatyajonnalagadda/miniforge3/envs/carbFL/lib/python3.10/site-packages/ray/_private/client_mode_hook.py", line 103, in wrapper
    return func(*args, **kwargs)
  File "/Users/saisatyajonnalagadda/miniforge3/envs/carbFL/lib/python3.10/site-packages/ray/_private/worker.py", line 2524, in get
    raise value.as_instanceof_cause()
ray.exceptions.RayTaskError: [36mray::DefaultActor.run()[39m (pid=93388, ip=127.0.0.1, actor_id=6e718db234739d23338590d901000000, repr=<flwr.simulation.ray_transport.ray_actor.DefaultActor object at 0x11220e020>)
ray.exceptions.OutOfDiskError: Local disk is full
The object cannot be created because the local object store is full and the local disk's utilization is over capacity (95% by default).Tip: Use `df` on this node to check disk usage and `ray memory` to check object store memory usage.

[2024-06-25 12:49:35,944][flwr][ERROR] - [36mray::DefaultActor.run()[39m (pid=93388, ip=127.0.0.1, actor_id=6e718db234739d23338590d901000000, repr=<flwr.simulation.ray_transport.ray_actor.DefaultActor object at 0x11220e020>)
  File "/Users/saisatyajonnalagadda/current_projects/carb_aware_model_adaption_FL/main2.py", line 116, in client_fn
    trainloader=trainloaders[client_id],
IndexError: list index out of range

The above exception was the direct cause of the following exception:

[36mray::DefaultActor.run()[39m (pid=93388, ip=127.0.0.1, actor_id=6e718db234739d23338590d901000000, repr=<flwr.simulation.ray_transport.ray_actor.DefaultActor object at 0x11220e020>)
  File "/Users/saisatyajonnalagadda/miniforge3/envs/carbFL/lib/python3.10/site-packages/flwr/simulation/ray_transport/ray_actor.py", line 84, in run
    raise ClientException(str(message)) from ex
flwr.simulation.ray_transport.ray_actor.ClientException: 
>>>>>>>A ClientException occurred.('\n\tSomething went wrong when running your client workload.\n\tClient 84_Mexico City_small crashed when the DefaultActor was running its workload.\n\tException triggered on the client side: Traceback (most recent call last):\n  File "/Users/saisatyajonnalagadda/miniforge3/envs/carbFL/lib/python3.10/site-packages/flwr/simulation/ray_transport/ray_actor.py", line 70, in run\n    client = check_clientfn_returns_client(client_fn(cid))\n  File "/Users/saisatyajonnalagadda/current_projects/carb_aware_model_adaption_FL/main2.py", line 116, in client_fn\n    trainloader=trainloaders[client_id],\nIndexError: list index out of range\n',)
[2024-06-25 12:49:35,944][flwr][ERROR] - [36mray::DefaultActor.run()[39m (pid=93386, ip=127.0.0.1, actor_id=58e61da2bd71ea42dec983a401000000, repr=<flwr.simulation.ray_transport.ray_actor.DefaultActor object at 0x11120e080>)
  File "/Users/saisatyajonnalagadda/current_projects/carb_aware_model_adaption_FL/main2.py", line 116, in client_fn
    trainloader=trainloaders[client_id],
IndexError: list index out of range

The above exception was the direct cause of the following exception:

[36mray::DefaultActor.run()[39m (pid=93386, ip=127.0.0.1, actor_id=58e61da2bd71ea42dec983a401000000, repr=<flwr.simulation.ray_transport.ray_actor.DefaultActor object at 0x11120e080>)
  File "/Users/saisatyajonnalagadda/miniforge3/envs/carbFL/lib/python3.10/site-packages/flwr/simulation/ray_transport/ray_actor.py", line 84, in run
    raise ClientException(str(message)) from ex
flwr.simulation.ray_transport.ray_actor.ClientException: 
>>>>>>>A ClientException occurred.('\n\tSomething went wrong when running your client workload.\n\tClient 73_Mexico City_small crashed when the DefaultActor was running its workload.\n\tException triggered on the client side: Traceback (most recent call last):\n  File "/Users/saisatyajonnalagadda/miniforge3/envs/carbFL/lib/python3.10/site-packages/flwr/simulation/ray_transport/ray_actor.py", line 70, in run\n    client = check_clientfn_returns_client(client_fn(cid))\n  File "/Users/saisatyajonnalagadda/current_projects/carb_aware_model_adaption_FL/main2.py", line 116, in client_fn\n    trainloader=trainloaders[client_id],\nIndexError: list index out of range\n',)
[2024-06-25 12:49:35,944][flwr][ERROR] - [36mray::DefaultActor.run()[39m (pid=93388, ip=127.0.0.1, actor_id=6e718db234739d23338590d901000000, repr=<flwr.simulation.ray_transport.ray_actor.DefaultActor object at 0x11220e020>)
ray.exceptions.OutOfDiskError: Local disk is full
The object cannot be created because the local object store is full and the local disk's utilization is over capacity (95% by default).Tip: Use `df` on this node to check disk usage and `ray memory` to check object store memory usage.
[2024-06-25 12:49:36,060][flwr][ERROR] - Traceback (most recent call last):
  File "/Users/saisatyajonnalagadda/miniforge3/envs/carbFL/lib/python3.10/site-packages/flwr/simulation/ray_transport/ray_client_proxy.py", line 138, in _submit_job
    res = self.actor_pool.get_client_result(self.cid, timeout)
  File "/Users/saisatyajonnalagadda/miniforge3/envs/carbFL/lib/python3.10/site-packages/flwr/simulation/ray_transport/ray_actor.py", line 414, in get_client_result
    return self._fetch_future_result(cid)
  File "/Users/saisatyajonnalagadda/miniforge3/envs/carbFL/lib/python3.10/site-packages/flwr/simulation/ray_transport/ray_actor.py", line 300, in _fetch_future_result
    res_cid, res = ray.get(future)  # type: (str, ClientRes)
  File "/Users/saisatyajonnalagadda/miniforge3/envs/carbFL/lib/python3.10/site-packages/ray/_private/auto_init_hook.py", line 24, in auto_init_wrapper
    return fn(*args, **kwargs)
  File "/Users/saisatyajonnalagadda/miniforge3/envs/carbFL/lib/python3.10/site-packages/ray/_private/client_mode_hook.py", line 103, in wrapper
    return func(*args, **kwargs)
  File "/Users/saisatyajonnalagadda/miniforge3/envs/carbFL/lib/python3.10/site-packages/ray/_private/worker.py", line 2524, in get
    raise value.as_instanceof_cause()
ray.exceptions.RayTaskError(ClientException): [36mray::DefaultActor.run()[39m (pid=93384, ip=127.0.0.1, actor_id=16813a4628b99ff15d870cfc01000000, repr=<flwr.simulation.ray_transport.ray_actor.DefaultActor object at 0x11c6fe020>)
  File "/Users/saisatyajonnalagadda/current_projects/carb_aware_model_adaption_FL/main2.py", line 116, in client_fn
    trainloader=trainloaders[client_id],
IndexError: list index out of range

The above exception was the direct cause of the following exception:

[36mray::DefaultActor.run()[39m (pid=93384, ip=127.0.0.1, actor_id=16813a4628b99ff15d870cfc01000000, repr=<flwr.simulation.ray_transport.ray_actor.DefaultActor object at 0x11c6fe020>)
  File "/Users/saisatyajonnalagadda/miniforge3/envs/carbFL/lib/python3.10/site-packages/flwr/simulation/ray_transport/ray_actor.py", line 84, in run
    raise ClientException(str(message)) from ex
flwr.simulation.ray_transport.ray_actor.ClientException: 
>>>>>>>A ClientException occurred.('\n\tSomething went wrong when running your client workload.\n\tClient 90_San Francisco_small crashed when the DefaultActor was running its workload.\n\tException triggered on the client side: Traceback (most recent call last):\n  File "/Users/saisatyajonnalagadda/miniforge3/envs/carbFL/lib/python3.10/site-packages/flwr/simulation/ray_transport/ray_actor.py", line 70, in run\n    client = check_clientfn_returns_client(client_fn(cid))\n  File "/Users/saisatyajonnalagadda/current_projects/carb_aware_model_adaption_FL/main2.py", line 116, in client_fn\n    trainloader=trainloaders[client_id],\nIndexError: list index out of range\n',)

[2024-06-25 12:49:36,060][flwr][ERROR] - [36mray::DefaultActor.run()[39m (pid=93384, ip=127.0.0.1, actor_id=16813a4628b99ff15d870cfc01000000, repr=<flwr.simulation.ray_transport.ray_actor.DefaultActor object at 0x11c6fe020>)
  File "/Users/saisatyajonnalagadda/current_projects/carb_aware_model_adaption_FL/main2.py", line 116, in client_fn
    trainloader=trainloaders[client_id],
IndexError: list index out of range

The above exception was the direct cause of the following exception:

[36mray::DefaultActor.run()[39m (pid=93384, ip=127.0.0.1, actor_id=16813a4628b99ff15d870cfc01000000, repr=<flwr.simulation.ray_transport.ray_actor.DefaultActor object at 0x11c6fe020>)
  File "/Users/saisatyajonnalagadda/miniforge3/envs/carbFL/lib/python3.10/site-packages/flwr/simulation/ray_transport/ray_actor.py", line 84, in run
    raise ClientException(str(message)) from ex
flwr.simulation.ray_transport.ray_actor.ClientException: 
>>>>>>>A ClientException occurred.('\n\tSomething went wrong when running your client workload.\n\tClient 90_San Francisco_small crashed when the DefaultActor was running its workload.\n\tException triggered on the client side: Traceback (most recent call last):\n  File "/Users/saisatyajonnalagadda/miniforge3/envs/carbFL/lib/python3.10/site-packages/flwr/simulation/ray_transport/ray_actor.py", line 70, in run\n    client = check_clientfn_returns_client(client_fn(cid))\n  File "/Users/saisatyajonnalagadda/current_projects/carb_aware_model_adaption_FL/main2.py", line 116, in client_fn\n    trainloader=trainloaders[client_id],\nIndexError: list index out of range\n',)
[2024-06-25 12:50:01,119][flwr][ERROR] - Traceback (most recent call last):
  File "/Users/saisatyajonnalagadda/miniforge3/envs/carbFL/lib/python3.10/site-packages/flwr/simulation/ray_transport/ray_client_proxy.py", line 138, in _submit_job
    res = self.actor_pool.get_client_result(self.cid, timeout)
  File "/Users/saisatyajonnalagadda/miniforge3/envs/carbFL/lib/python3.10/site-packages/flwr/simulation/ray_transport/ray_actor.py", line 414, in get_client_result
    return self._fetch_future_result(cid)
  File "/Users/saisatyajonnalagadda/miniforge3/envs/carbFL/lib/python3.10/site-packages/flwr/simulation/ray_transport/ray_actor.py", line 300, in _fetch_future_result
    res_cid, res = ray.get(future)  # type: (str, ClientRes)
  File "/Users/saisatyajonnalagadda/miniforge3/envs/carbFL/lib/python3.10/site-packages/ray/_private/auto_init_hook.py", line 24, in auto_init_wrapper
    return fn(*args, **kwargs)
  File "/Users/saisatyajonnalagadda/miniforge3/envs/carbFL/lib/python3.10/site-packages/ray/_private/client_mode_hook.py", line 103, in wrapper
    return func(*args, **kwargs)
  File "/Users/saisatyajonnalagadda/miniforge3/envs/carbFL/lib/python3.10/site-packages/ray/_private/worker.py", line 2524, in get
    raise value.as_instanceof_cause()
ray.exceptions.RayTaskError(ClientException): [36mray::DefaultActor.run()[39m (pid=93389, ip=127.0.0.1, actor_id=14db2c5b5d750a6eeb0804e601000000, repr=<flwr.simulation.ray_transport.ray_actor.DefaultActor object at 0x12200e050>)
  File "/Users/saisatyajonnalagadda/current_projects/carb_aware_model_adaption_FL/main2.py", line 116, in client_fn
    trainloader=trainloaders[client_id],
IndexError: list index out of range

The above exception was the direct cause of the following exception:

[36mray::DefaultActor.run()[39m (pid=93389, ip=127.0.0.1, actor_id=14db2c5b5d750a6eeb0804e601000000, repr=<flwr.simulation.ray_transport.ray_actor.DefaultActor object at 0x12200e050>)
  File "/Users/saisatyajonnalagadda/miniforge3/envs/carbFL/lib/python3.10/site-packages/flwr/simulation/ray_transport/ray_actor.py", line 84, in run
    raise ClientException(str(message)) from ex
flwr.simulation.ray_transport.ray_actor.ClientException: 
>>>>>>>A ClientException occurred.('\n\tSomething went wrong when running your client workload.\n\tClient 68_Sydney_small crashed when the DefaultActor was running its workload.\n\tException triggered on the client side: Traceback (most recent call last):\n  File "/Users/saisatyajonnalagadda/miniforge3/envs/carbFL/lib/python3.10/site-packages/flwr/simulation/ray_transport/ray_actor.py", line 70, in run\n    client = check_clientfn_returns_client(client_fn(cid))\n  File "/Users/saisatyajonnalagadda/current_projects/carb_aware_model_adaption_FL/main2.py", line 116, in client_fn\n    trainloader=trainloaders[client_id],\nIndexError: list index out of range\n',)

[2024-06-25 12:50:01,121][flwr][ERROR] - [36mray::DefaultActor.run()[39m (pid=93389, ip=127.0.0.1, actor_id=14db2c5b5d750a6eeb0804e601000000, repr=<flwr.simulation.ray_transport.ray_actor.DefaultActor object at 0x12200e050>)
  File "/Users/saisatyajonnalagadda/current_projects/carb_aware_model_adaption_FL/main2.py", line 116, in client_fn
    trainloader=trainloaders[client_id],
IndexError: list index out of range

The above exception was the direct cause of the following exception:

[36mray::DefaultActor.run()[39m (pid=93389, ip=127.0.0.1, actor_id=14db2c5b5d750a6eeb0804e601000000, repr=<flwr.simulation.ray_transport.ray_actor.DefaultActor object at 0x12200e050>)
  File "/Users/saisatyajonnalagadda/miniforge3/envs/carbFL/lib/python3.10/site-packages/flwr/simulation/ray_transport/ray_actor.py", line 84, in run
    raise ClientException(str(message)) from ex
flwr.simulation.ray_transport.ray_actor.ClientException: 
>>>>>>>A ClientException occurred.('\n\tSomething went wrong when running your client workload.\n\tClient 68_Sydney_small crashed when the DefaultActor was running its workload.\n\tException triggered on the client side: Traceback (most recent call last):\n  File "/Users/saisatyajonnalagadda/miniforge3/envs/carbFL/lib/python3.10/site-packages/flwr/simulation/ray_transport/ray_actor.py", line 70, in run\n    client = check_clientfn_returns_client(client_fn(cid))\n  File "/Users/saisatyajonnalagadda/current_projects/carb_aware_model_adaption_FL/main2.py", line 116, in client_fn\n    trainloader=trainloaders[client_id],\nIndexError: list index out of range\n',)
[2024-06-25 12:50:01,123][flwr][DEBUG] - fit_round 1 received 14 results and 21 failures
[2024-06-25 12:50:02,663][flwr][WARNING] - No fit_metrics_aggregation_fn provided
[2024-06-25 12:50:16,541][flwr][INFO] - fit progress: (1, 0.1952660605788231, {'accuracy': 0.3347}, 200.56340475000616)
[2024-06-25 12:50:16,541][flwr][INFO] - evaluate_round 1: no clients selected, cancel
[2024-06-25 12:50:16,541][flwr][INFO] - FL finished in 200.56374091700127
[2024-06-25 12:50:16,600][flwr][INFO] - app_fit: losses_distributed []
[2024-06-25 12:50:16,600][flwr][INFO] - app_fit: metrics_distributed_fit {}
[2024-06-25 12:50:16,600][flwr][INFO] - app_fit: metrics_distributed {}
[2024-06-25 12:50:16,600][flwr][INFO] - app_fit: losses_centralized [(0, 0.2418656432390213), (1, 0.1952660605788231)]
[2024-06-25 12:50:16,600][flwr][INFO] - app_fit: metrics_centralized {'accuracy': [(0, 0.1085), (1, 0.3347)]}
